Workbook

Sheet Coefs
E1: ROOTS | G1: DRY MATTER | I1: WEEDS | K1: PRODUCT ENERGY | N1: RESIDUE ENERGY | O1: HARVEST INDEX | P1: RESIDUES INDICES | T1: NUTRIENTS IN EDIBLE PART | AI1: HARVESTED PRODUCT | AM1: RESIDUE | AR1: Density | AS1: Root C | BA1: 2
A2: Code | B2: Name_biomass | C2: Equiv | D2: Category | E2: BG_Biomass_kgDM_ha | F2: Root_Shoot_ratio | G2: Product_kgDM_kgFM | H2: Residue_kgDM_kgFM | I2: Conventional_kgDM_ha | J2: Organic_kgDM_ha | K2: GE_product_edible_portion_MJ_kgFM | L2: GE_product_residue_MJ_kgFM | M2: GE_product_MJ_kgFM | N2: GE_residue_MJ_kg | O2: kg_product_kg_aerial_biomass | P2: kg_residue_kg_aerial_biomass_FM | Q2: kg_residue_kg_product_FM | R2: Carcass_to_LW | S2: Edible_portion | T2: N_kgN_kgFM | U2: Lipids_g_kgFM | V2: Carbohydrates_g_kgFM | W2: Calcium_mg_kgFM | X2: VitaminA_microg_kgFM | Y2: Edible_kgDM_kgFM | Z2: Edible_kgC_kgFM | AA2: Edible_N_kgFM | AB2: Edible_kgP_kgFM | AC2: Edible_K_kgFM | AD2: NonEdible_kgDM_kgFM | AE2: NonEdible_kgC_kgFM | AF2: NonEdible_kgN_kgFM | AG2: NonEdible_kgP_kgFM | AH2: NonEdible_kgK_kgFM | AI2: Product_kgN_kgDM | AJ2: Product_kgP_kgDM | AK2: Product_kgK_kgDM | AL2: Product_kgC_kgDM | AM2: Residue_kgN_kgDM | AN2: Residue_kgP_kgDM | AO2: Residue_kgK_kgDM | AP2: Residue_kgC_kgDM | AQ2: Residue_humified_kgC_kgC | AR2: MgDM_m3 | AS2: Root_kgC_kgDM | AT2: Root_humified_kgC_kgC | AU2: Root_mass_kgC_kgDM | AV2: Rhizodeposits_mass_kgC_kgDM | AW2: Residue_C_N | AX2: Root_kgN_kgDM | AY2: GE_Roots_MJ_kgDM | AZ2: Rhizodeposits_N_kgN_kgRootN | BA2: Fiber_g_kgFM | BB2: SFA_g_kgFM | BC2: MUFA_g_kgFM | BD2: PUFA_g_kgFM | BE2: PUFA_n3_g_kgFM | BF2: Iron_mg_kgFM | BG2: Zinc_mg_kgFM | BH2: Magnesium_mg_kgFM | BI2: Cadmium_microg_kgFM | BJ2: VitaminB12_microg_kgFM | BK2: VitaminD_microg_kgFM | BL2: Folate_microg_kgFM | BM2: VitaminC_mg_kgFM | BN2: VitaminE_mg_kgFM | BO2: Flavonoids_mg_kgFM | BP2: Carotenoids_mg_kgFM
A3: 75 | B3: Oats | C3: Wheat | D3: Cereals, other | E3: 3393.3333 | F3: 0.40240406 | G3: 0.86733333 | H3: 0.907 | I3: 232.075 | J3: 873.33823 | M3: 15.176 | N3: 15.93853 | O3: 0.41217502 | P3: 0.58782498 | Q3: 1.4261538 | S3: =VLOOKUP($B3,Conversores_Dieta!$B$4:$J$164,Coefs!S$292,0) -> 1 | T3: =AI3*G3 -> 0.013414756 | U3: =VLOOKUP($B3,Conversores_Dieta!$B$4:$J$164,Coefs!U$292,0) -> 71 | V3: =VLOOKUP($B3,Conversores_Dieta!$B$4:$J$164,Coefs!V$292,0) -> 598 | W3: =VLOOKUP($B3,Conversores_Dieta!$B$4:$J$164,Coefs!W$292,0) -> 796 | X3: =VLOOKUP($B3,Conversores_Dieta!$B$4:$J$164,Coefs!X$292,0) -> 0 | AI3: 0.015466667 | AJ3: 0.0036666667 | AK3: 0.004 | AL3: 0.46 | AM3: 0.007 | AN3: 0.00076335878 | AO3: 0.011995638 | AP3: 0.47206667 | AQ3: 0.11534667 | AS3: 0.76065 | AT3: =$AT$228 -> 0.17824592 | AU3: 0.461 | AV3: 0.29965 | AX3: =AI3*O3+P3*AM3 -> 0.010489748 | AY3: 17.5728 | AZ3: 0.7 | BA3: 106 | BB3: 12 | BC3: 22 | BD3: 25 | BE3: 0 | BF3: 47.2 | BG3: 39.7 | BH3: 1770 | BI3: 33.4 | BJ3: 0 | BK3: 0 | BL3: 560 | BM3: 0 | BN3: 7 | BO3: 200 | BP3: 3
A4: 44 | B4: Barley | C4: Wheat | D4: Barley | E4: 1543.9523 | F4: 0.21011179 | G4: 0.885 | H4: 0.864 | I4: 232.075 | J4: 873.33823 | M4: 15.626 | N4: 15.182899 | O4: 0.45373031 | P4: 0.54626969 | Q4: 1.2039524 | S4: =VLOOKUP(C4,$B$3:$X$358,MATCH(S$2,$B$2:$X$2,0),0) -> 1 | T4: =AI4*G4 -> 0.016480821 | U4: =VLOOKUP($C4,$B$3:$X$358,MATCH(U$2,$B$2:$X$2,0),0)*$G4/VLOOKUP($C4,$B$3:$X$358,MATCH($G$2,$B$2:$X$2,0),0) -> 12.081911 | V4: =VLOOKUP($C4,$B$3:$X$358,MATCH(V$2,$B$2:$X$2,0),0)*$G4/VLOOKUP($C4,$B$3:$X$358,MATCH($G$2,$B$2:$X$2,0),0) -> 805.46075 | W4: =VLOOKUP($C4,$B$3:$X$358,MATCH(W$2,$B$2:$X$2,0),0)*$G4/VLOOKUP($C4,$B$3:$X$358,MATCH($G$2,$B$2:$X$2,0),0) -> 151.02389 | X4: =VLOOKUP($C4,$B$3:$X$358,MATCH(X$2,$B$2:$X$2,0),0)*$G4/VLOOKUP($C4,$B$3:$X$358,MATCH($G$2,$B$2:$X$2,0),0) -> 0 | AI4: 0.018622397 | AJ4: 0.0037872787 | AK4: 0.0044569366 | AL4: 0.46 | AM4: 0.007 | AN4: 0.00076335878 | AO4: 0.011995638 | AP4: 0.4467 | AQ4: 0.11534667 | AS4: 0.8085 | AT4: =$AT$228 -> 0.17824592 | AU4: 0.49 | AV4: 0.3185 | AX4: =AI4*O4+P4*AM4 -> 0.012273434 | AY4: 17.5728 | AZ4: 0.7 | BA4: 148 | BB4: 3 | BC4: 2 | BD4: 7 | BE4: 0 | BF4: 60 | BG4: 33 | BH4: 910 | BI4: 33.4 | BJ4: 0 | BK4: 0 | BL4: 500 | BM4: 100 | BN4: 2 | BO4: 600 | BP4: 5
A5: 27 | B5: Rice | D5: Rice | F5: 0.22 | G5: 0.864 | H5: 0.91 | I5: 232.075 | J5: 873.33823 | M5: 15.176 | N5: 15.991248 | O5: 0.45454545 | P5: 0.54545455 | Q5: 1.2 | S5: =VLOOKUP($B5,Conversores_Dieta!$B$4:$J$164,Coefs!S$292,0) -> 1 | T5: =AI5*G5 -> 0.011889908 | U5: =VLOOKUP($B5,Conversores_Dieta!$B$4:$J$164,Coefs!U$292,0) -> 9 | V5: =VLOOKUP($B5,Conversores_Dieta!$B$4:$J$164,Coefs!V$292,0) -> 860 | W5: =VLOOKUP($B5,Conversores_Dieta!$B$4:$J$164,Coefs!W$292,0) -> 100 | X5: =VLOOKUP($B5,Conversores_Dieta!$B$4:$J$164,Coefs!X$292,0) -> 0 | AI5: 0.013761468 | AJ5: 0.001146789 | AK5: 0.0013761468 | AL5: 0.46 | AM5: 0.007 | AN5: 0.00076335878 | AO5: 0.011995638 | AP5: 0.40053571 | AQ5: 0.11534667 | AS5: 0.51315 | AT5: =$AT$228 -> 0.17824592 | AU5: 0.311 | AV5: 0.20215 | AX5: =AI5*O5+P5*AM5 -> 0.010073394 | AY5: 17.5728 | AZ5: 0.7 | BA5: 18.5 | BB5: 2.1 | BC5: 2.3 | BD5: 3.2 | BE5: 0 | BF5: 5 | BG5: 2 | BH5: 130 | BI5: 33.4 | BJ5: 0 | BK5: 0 | BL5: 200 | BM5: 0 | BN5: 3 | BO5: 300 | BP5: 0
A6: 79 | B6: Millet | C6: Maize | D6: Cereals, other | F6: 0.25 | G6: 0.8805 | H6: 0.9 | I6: 232.075 | J6: 873.33823 | M6: 15.1238 | N6: 15.81552 | O6: 0.45 | P6: 0.55 | Q6: 1.2222222 | S6: =VLOOKUP(C6,$B$3:$X$358,MATCH(S$2,$B$2:$X$2,0),0) -> 1 | T6: =AI6*G6 -> 0.013579852 | U6: =VLOOKUP($C6,$B$3:$X$358,MATCH(U$2,$B$2:$X$2,0),0)*$G6/VLOOKUP($C6,$B$3:$X$358,MATCH($G$2,$B$2:$X$2,0),0) -> 27.579466 | V6: =VLOOKUP($C6,$B$3:$X$358,MATCH(V$2,$B$2:$X$2,0),0)*$G6/VLOOKUP($C6,$B$3:$X$358,MATCH($G$2,$B$2:$X$2,0),0) -> 776.3109 | W6: =VLOOKUP($C6,$B$3:$X$358,MATCH(W$2,$B$2:$X$2,0),0)*$G6/VLOOKUP($C6,$B$3:$X$358,MATCH($G$2,$B$2:$X$2,0),0) -> 122.57541 | X6: =VLOOKUP($C6,$B$3:$X$358,MATCH(X$2,$B$2:$X$2,0),0)*$G6/VLOOKUP($C6,$B$3:$X$358,MATCH($G$2,$B$2:$X$2,0),0) -> 0 | AI6: 0.015422887 | AJ6: 0.0032554604 | AK6: 0.00383284 | AL6: 0.46 | AM6: 0.007 | AN6: 0.00076335878 | AO6: 0.011995638 | AP6: 0.42792857 | AQ6: 0.11534667 | AS6: 0.7392 | AT6: =$AT$228 -> 0.17824592 | AU6: 0.448 | AV6: 0.2912 | AX6: =AI6*O6+P6*AM6 -> 0.010790299 | AY6: 17.5728 | AZ6: 0.7 | BA6: =BA8 -> 70 | BB6: =BB8 -> 6.1 | BC6: =BC8 -> 9.8 | BD6: =BD8 -> 17.5 | BE6: =BE8 -> 0 | BF6: =BF8 -> 39 | BG6: =BG8 -> 30 | BH6: =BH8 -> 1300 | ... BP6: =BP8 -> 3
A7: 71 | B7: Rye | D7: Cereals, other | F7: 0.14 | G7: 0.876 | H7: 0.924 | I7: 232.075 | J7: 873.33823 | M7: 14.137 | N7: 16.237267 | O7: 0.43478261 | P7: 0.56521739 | Q7: 1.3 | S7: =VLOOKUP($B7,Conversores_Dieta!$B$4:$J$164,Coefs!S$292,0) -> 1 | T7: =AI7*G7 -> 0.013670314 | U7: =VLOOKUP($B7,Conversores_Dieta!$B$4:$J$164,Coefs!U$292,0) -> 19.3 | V7: =VLOOKUP($B7,Conversores_Dieta!$B$4:$J$164,Coefs!V$292,0) -> 597 | W7: =VLOOKUP($B7,Conversores_Dieta!$B$4:$J$164,Coefs!W$292,0) -> 270 | X7: =VLOOKUP($B7,Conversores_Dieta!$B$4:$J$164,Coefs!X$292,0) -> 0 | AI7: 0.015605381 | AJ7: 0.0033632287 | AK7: 0.0044843049 | AL7: 0.46 | AM7: 0.005 | AN7: 0.00076335878 | AO7: 0.011995638 | AP7: 0.47424 | AQ7: 0.11534667 | AS7: 0.6996 | AT7: =$AT$228 -> 0.17824592 | AU7: 0.424 | AV7: 0.2756 | AX7: =AI7*O7+P7*AM7 -> 0.0096110353 | AY7: 17.5728 | AZ7: 0.7 | BA7: 146 | BB7: 2.9 | BC7: 3 | BD7: 11 | BE7: 0 | BF7: 26.7 | BG7: 37.3 | BH7: 1210 | BI7: 33.4 | BJ7: 0 | BK7: 0 | BL7: 600 | BM7: 0 | BN7: 18.7 | BO7: 300 | BP7: 3.5
A8: 83 | B8: Sorghum | C8: Maize | D8: Cereals, other | F8: 0.086206897 | G8: 0.865 | H8: 0.87 | I8: 232.075 | J8: 873.33823 | M8: 15.98288 | N8: 15.288336 | O8: 0.37234493 | P8: 0.62765507 | Q8: 1.6856818 | S8: =VLOOKUP(C8,$B$3:$X$358,MATCH(S$2,$B$2:$X$2,0),0) -> 1 | T8: 0.01616 | U8: =VLOOKUP($C8,$B$3:$X$358,MATCH(U$2,$B$2:$X$2,0),0)*$G8/VLOOKUP($C8,$B$3:$X$358,MATCH($G$2,$B$2:$X$2,0),0) -> 27.093968 | V8: =VLOOKUP($C8,$B$3:$X$358,MATCH(V$2,$B$2:$X$2,0),0)*$G8/VLOOKUP($C8,$B$3:$X$358,MATCH($G$2,$B$2:$X$2,0),0) -> 762.64501 | W8: =VLOOKUP($C8,$B$3:$X$358,MATCH(W$2,$B$2:$X$2,0),0)*$G8/VLOOKUP($C8,$B$3:$X$358,MATCH($G$2,$B$2:$X$2,0),0) -> 120.41763 | X8: =VLOOKUP($C8,$B$3:$X$358,MATCH(X$2,$B$2:$X$2,0),0)*$G8/VLOOKUP($C8,$B$3:$X$358,MATCH($G$2,$B$2:$X$2,0),0) -> 0 | AI8: =T8/G8 -> 0.018682081 | AJ8: 0.0034482759 | AK8: 0.0040229885 | AL8: 0.46 | AM8: 0.007 | AN8: 0.00076335878 | AO8: 0.011995638 | AP8: 0.45564 | AQ8: 0.11534667 | AS8: 0.7656 | AT8: =$AT$228 -> 0.17824592 | AU8: 0.464 | AV8: 0.3016 | AX8: =AI8*O8+P8*AM8 -> 0.011349764 | AY8: 17.5728 | AZ8: 0.7 | BA8: 70 | BB8: 6.1 | BC8: 9.8 | BD8: 17.5 | BE8: 0 | BF8: 39 | BG8: 30 | BH8: 1300 | BI8: 33.4 | BJ8: 0 | BK8: 0 | BL8: 384 | BM8: 0 | BN8: 8.1 | BO8: 900 | BP8: 3
A9: 15 | B9: Wheat | D9: Wheat | E9: 2028.6684 | F9: 0.20340943 | G9: 0.879 | H9: 0.8665 | I9: 232.075 | J9: 873.33823 | M9: 15.226831 | N9: 15.226831 | O9: 0.42347951 | P9: 0.57652049 | Q9: 1.3613893 | S9: =VLOOKUP($B9,Conversores_Dieta!$B$4:$J$164,Coefs!S$292,0) -> 1 | T9: =AI9*G9 -> 0.018951324 | U9: =VLOOKUP($B9,Conversores_Dieta!$B$4:$J$164,Coefs!U$292,0) -> 12 | V9: =VLOOKUP($B9,Conversores_Dieta!$B$4:$J$164,Coefs!V$292,0) -> 800 | W9: =VLOOKUP($B9,Conversores_Dieta!$B$4:$J$164,Coefs!W$292,0) -> 150 | X9: =VLOOKUP($B9,Conversores_Dieta!$B$4:$J$164,Coefs!X$292,0) -> 0 | AI9: 0.021560096 | AJ9: 0.003514448 | AK9: 0.0040126526 | AL9: 0.46 | AM9: 0.00592 | AN9: 0.00076335878 | AO9: 0.011995638 | AP9: 0.4579975 | AQ9: 0.11534667 | AS9: 0.7656 | AT9: =$AT$228 -> 0.17824592 | AU9: 0.464 | AV9: 0.3016 | AX9: =AI9*O9+P9*AM9 -> 0.01254326 | AY9: 17.5728 | AZ9: 0.7 | BA9: 10 | BB9: 3.7 | BC9: 2.7 | BD9: 11 | BE9: 0 | BF9: 33 | BG9: 41 | BH9: 1470 | BI9: 33.4 | BJ9: 0 | BK9: 0 | BL9: 490 | BM9: 0 | BN9: 14 | BO9: 325 | BP9: 5.5
A10: 56 | B10: Maize | D10: Maize | E10: 4615.7778 | F10: 0.24305481 | G10: 0.862 | H10: 0.881 | I10: 232.075 | J10: 873.33823 | M10: 14.4384 | N10: 15.481637 | O10: 0.51510322 | P10: 0.48489678 | Q10: 0.94135849 | S10: =VLOOKUP($B10,Conversores_Dieta!$B$4:$J$164,Coefs!S$292,0) -> 1 | T10: =AI10*G10 -> 0.01248 | U10: =VLOOKUP($B10,Conversores_Dieta!$B$4:$J$164,Coefs!U$292,0) -> 27 | V10: =VLOOKUP($B10,Conversores_Dieta!$B$4:$J$164,Coefs!V$292,0) -> 760 | W10: =VLOOKUP($B10,Conversores_Dieta!$B$4:$J$164,Coefs!W$292,0) -> 120 | X10: =VLOOKUP($B10,Conversores_Dieta!$B$4:$J$164,Coefs!X$292,0) -> 0 | AI10: 0.014477958 | AJ10: 0.003062645 | AK10: 0.0036426914 | AL10: 0.44 | AM10: 0.00592 | AN10: 0.00076335878 | AO10: 0.011995638 | AP10: 0.43383889 | AQ10: 0.11534667 | AS10: 0.6798 | AT10: =$AT$228 -> 0.17824592 | AU10: 0.412 | AV10: 0.2678 | AX10: =AI10*O10+P10*AM10 -> 0.010328232 | AY10: 17.5728 | AZ10: 0.7 | BA10: 27 | BB10: 1.3 | BC10: 2.4 | BD10: 4.2 | BE10: 0 | BF10: 7 | BG10: 3 | BH10: 300 | BI10: 33.4 | BJ10: 0 | BK10: 0 | BL10: 300 | BM10: 60 | BN10: 4 | BO10: 600 | BP10: 37.5
B11: Winter cereals, other | C11: Wheat | D11: Cereals, other | F11: =AVERAGE(F3:F4,F7,F9) -> 0.23898132 | G11: 0.87258333 | H11: 0.890375 | I11: 232.075 | J11: 873.33823 | M11: 14.911096 | N11: 15.646382 | O11: 0.45 | P11: 0.55 | Q11: 1.2222222 | S11: =VLOOKUP(C11,$B$3:$X$358,MATCH(S$2,$B$2:$X$2,0),0) -> 1 | T11: =AI11*G11 -> 0.016023208 | U11: =VLOOKUP($C11,$B$3:$X$358,MATCH(U$2,$B$2:$X$2,0),0)*$G11/VLOOKUP($C11,$B$3:$X$358,MATCH($G$2,$B$2:$X$2,0),0) -> 11.9124 | V11: =VLOOKUP($C11,$B$3:$X$358,MATCH(V$2,$B$2:$X$2,0),0)*$G11/VLOOKUP($C11,$B$3:$X$358,MATCH($G$2,$B$2:$X$2,0),0) -> 794.16003 | W11: =VLOOKUP($C11,$B$3:$X$358,MATCH(W$2,$B$2:$X$2,0),0)*$G11/VLOOKUP($C11,$B$3:$X$358,MATCH($G$2,$B$2:$X$2,0),0) -> 148.90501 | X11: =VLOOKUP($C11,$B$3:$X$358,MATCH(X$2,$B$2:$X$2,0),0)*$G11/VLOOKUP($C11,$B$3:$X$358,MATCH($G$2,$B$2:$X$2,0),0) -> 0 | AI11: 0.018362955 | AJ11: 0.0036561311 | AK11: 0.0041565297 | AL11: 0.46 | AM11: 0.00592 | AN11: 0.00076335878 | AO11: 0.011995638 | AP11: 0.45761311 | AQ11: 0.11534667 | AS11: 0.721765 | AT11: =$AT$228 -> 0.17824592 | AU11: 0.43743333 | AV11: 0.28433167 | AX11: =AI11*O11+P11*AM11 -> 0.01151933 | AY11: 17.5728 | AZ11: 0.7 | BA11: 133.3 | BB11: 7.9 | BC11: 12.4 | BD11: 18 | BE11: 0 | BF11: 40 | BG11: 36.7 | BH11: 1296.7 | BI11: 33.4 | BJ11: 0 | BK11: 0 | BL11: 530 | BM11: 0 | BN11: 7.7 | BO11: 550 | BP11: 3
B12: Summer cereals, other | C12: Maize | D12: Cereals, other | F12: =AVERAGE(F5:F6,F8,F10) -> 0.19981543 | G12: 0.8635 | H12: 0.8755 | I12: 232.075 | J12: 873.33823 | M12: 15.21064 | N12: 15.384986 | O12: 0.45 | P12: 0.55 | Q12: 1.2222222 | S12: =VLOOKUP(C12,$B$3:$X$358,MATCH(S$2,$B$2:$X$2,0),0) -> 1 | T12: =AI12*G12 -> 0.013317663 | U12: =VLOOKUP($C12,$B$3:$X$358,MATCH(U$2,$B$2:$X$2,0),0)*$G12/VLOOKUP($C12,$B$3:$X$358,MATCH($G$2,$B$2:$X$2,0),0) -> 27.046984 | V12: =VLOOKUP($C12,$B$3:$X$358,MATCH(V$2,$B$2:$X$2,0),0)*$G12/VLOOKUP($C12,$B$3:$X$358,MATCH($G$2,$B$2:$X$2,0),0) -> 761.32251 | W12: =VLOOKUP($C12,$B$3:$X$358,MATCH(W$2,$B$2:$X$2,0),0)*$G12/VLOOKUP($C12,$B$3:$X$358,MATCH($G$2,$B$2:$X$2,0),0) -> 120.20882 | X12: =VLOOKUP($C12,$B$3:$X$358,MATCH(X$2,$B$2:$X$2,0),0)*$G12/VLOOKUP($C12,$B$3:$X$358,MATCH($G$2,$B$2:$X$2,0),0) -> 0 | AI12: 0.015422887 | AJ12: 0.0032554604 | AK12: 0.00383284 | AL12: 0.455 | AM12: 0.00592 | AN12: 0.00076335878 | AO12: 0.011995638 | AP12: 0.42792857 | AQ12: 0.11534667 | AS12: 0.69278 | AT12: =$AT$228 -> 0.17824592 | AU12: 0.41986667 | AV12: 0.27291333 | AX12: =AI12*O12+P12*AM12 -> 0.010196299 | AY12: 17.5728 | AZ12: 0.7 | BA12: 50 | BB12: 1.7 | BC12: 2.4 | BD12: 3.7 | BE12: 0 | BF12: 6 | BG12: 16 | BH12: 715 | BI12: 33.4 | BJ12: 0 | BK12: 0 | BL12: 250 | BM12: 60 | BN12: 5 | BO12: 800 | BP12: 2.5
A13: 97 | B13: Triticale | C13: Wheat | D13: Cereals, other | F13: =$F$11 -> 0.23898132 | G13: =$G$11 -> 0.87258333 | H13: =$H$11 -> 0.890375 | I13: =$I$11 -> 232.075 | J13: =$J$11 -> 873.33823 | M13: =$M$11 -> 14.911096 | N13: =$N$11 -> 15.646382 | O13: =$O$11 -> 0.45 | P13: =$P$11 -> 0.55 | Q13: =$Q$11 -> 1.2222222 | S13: =VLOOKUP(C13,$B$3:$X$358,MATCH(S$2,$B$2:$X$2,0),0) -> 1 | T13: =AI13*G13 -> 0.016023208 | U13: =VLOOKUP($C13,$B$3:$X$358,MATCH(U$2,$B$2:$X$2,0),0)*$G13/VLOOKUP($C13,$B$3:$X$358,MATCH($G$2,$B$2:$X$2,0),0) -> 11.9124 | V13: =VLOOKUP($C13,$B$3:$X$358,MATCH(V$2,$B$2:$X$2,0),0)*$G13/VLOOKUP($C13,$B$3:$X$358,MATCH($G$2,$B$2:$X$2,0),0) -> 794.16003 | W13: =VLOOKUP($C13,$B$3:$X$358,MATCH(W$2,$B$2:$X$2,0),0)*$G13/VLOOKUP($C13,$B$3:$X$358,MATCH($G$2,$B$2:$X$2,0),0) -> 148.90501 | X13: =VLOOKUP($C13,$B$3:$X$358,MATCH(X$2,$B$2:$X$2,0),0)*$G13/VLOOKUP($C13,$B$3:$X$358,MATCH($G$2,$B$2:$X$2,0),0) -> 0 | AI13: =$AI$11 -> 0.018362955 | AJ13: =$AJ$11 -> 0.0036561311 | AK13: =$AK$11 -> 0.0041565297 | AL13: =$AL$11 -> 0.46 | AM13: 0.00592 | AN13: =$AN$11 -> 0.00076335878 | AO13: =$AO$11 -> 0.011995638 | AP13: =$AP$11 -> 0.45761311 | AQ13: =$AQ$11 -> 0.11534667 | AS13: =$AS$11 -> 0.721765 | AT13: =$AT$228 -> 0.17824592 | AU13: =$AU$11 -> 0.43743333 | AV13: =$AV$11 -> 0.28433167 | AX13: =AI13*O13+P13*AM13 -> 0.01151933 | AY13: =$AY$11 -> 17.5728 | AZ13: 0.7 | BA13: 105 | BB13: 3 | BC13: 2 | BD13: 8 | BE13: 0 | BF13: 26 | BG13: 25 | BH13: 1100 | BI13: 33.4 | BJ13: 0 | BK13: 0 | BL13: 740 | BM13: 0 | BN13: 9 | BO13: 250 | BP13: 3.5
A14: 101 | B14: Canary grass | C14: Wheat | D14: Cereals, other | F14: =$F$11 -> 0.23898132 | G14: =$G$11 -> 0.87258333 | H14: =$H$11 -> 0.890375 | I14: =$I$11 -> 232.075 | J14: =$J$11 -> 873.33823 | M14: =$M$11 -> 14.911096 | N14: =$N$11 -> 15.646382 | O14: =$O$11 -> 0.45 | P14: =$P$11 -> 0.55 | Q14: =$Q$11 -> 1.2222222 | S14: =VLOOKUP(C14,$B$3:$X$358,MATCH(S$2,$B$2:$X$2,0),0) -> 1 | T14: =AI14*G14 -> 0.016023208 | U14: =VLOOKUP($C14,$B$3:$X$358,MATCH(U$2,$B$2:$X$2,0),0)*$G14/VLOOKUP($C14,$B$3:$X$358,MATCH($G$2,$B$2:$X$2,0),0) -> 11.9124 | V14: =VLOOKUP($C14,$B$3:$X$358,MATCH(V$2,$B$2:$X$2,0),0)*$G14/VLOOKUP($C14,$B$3:$X$358,MATCH($G$2,$B$2:$X$2,0),0) -> 794.16003 | W14: =VLOOKUP($C14,$B$3:$X$358,MATCH(W$2,$B$2:$X$2,0),0)*$G14/VLOOKUP($C14,$B$3:$X$358,MATCH($G$2,$B$2:$X$2,0),0) -> 148.90501 | X14: =VLOOKUP($C14,$B$3:$X$358,MATCH(X$2,$B$2:$X$2,0),0)*$G14/VLOOKUP($C14,$B$3:$X$358,MATCH($G$2,$B$2:$X$2,0),0) -> 0 | AI14: =$AI$11 -> 0.018362955 | AJ14: =$AJ$11 -> 0.0036561311 | AK14: =$AK$11 -> 0.0041565297 | AL14: =$AL$11 -> 0.46 | AM14: 0.00592 | AN14: =$AN$11 -> 0.00076335878 | AO14: =$AO$11 -> 0.011995638 | AP14: =$AP$11 -> 0.45761311 | AQ14: =$AQ$11 -> 0.11534667 | AS14: =$AS$11 -> 0.721765 | AT14: =$AT$228 -> 0.17824592 | AU14: =$AU$11 -> 0.43743333 | AV14: =$AV$11 -> 0.28433167 | AX14: =AI14*O14+P14*AM14 -> 0.01151933 | AY14: =$AY$11 -> 17.5728 | AZ14: 0.7 | BA14: 130 | BB14: 7.1 | BC14: 12 | BD14: 32.9 | BE14: 0 | BF14: 0 | BG14: 30 | BH14: 1200 | BI14: 33.4 | BJ14: 0 | BK14: 0 | BL14: 550 | BM14: 0 | BN14: 6 | BO14: 300 | BP14: 3
A15: 108 | B15: Cereals nes | C15: Wheat | D15: Cereals, other | F15: =$F$11 -> 0.23898132 | G15: =$G$11 -> 0.87258333 | H15: =$H$11 -> 0.890375 | I15: =$I$11 -> 232.075 | J15: =$J$11 -> 873.33823 | M15: =$M$11 -> 14.911096 | N15: =$N$11 -> 15.646382 | O15: =$O$11 -> 0.45 | P15: =$P$11 -> 0.55 | Q15: =$Q$11 -> 1.2222222 | S15: =VLOOKUP(C15,$B$3:$X$358,MATCH(S$2,$B$2:$X$2,0),0) -> 1 | T15: =AI15*G15 -> 0.016023208 | U15: =VLOOKUP($C15,$B$3:$X$358,MATCH(U$2,$B$2:$X$2,0),0)*$G15/VLOOKUP($C15,$B$3:$X$358,MATCH($G$2,$B$2:$X$2,0),0) -> 11.9124 | V15: =VLOOKUP($C15,$B$3:$X$358,MATCH(V$2,$B$2:$X$2,0),0)*$G15/VLOOKUP($C15,$B$3:$X$358,MATCH($G$2,$B$2:$X$2,0),0) -> 794.16003 | W15: =VLOOKUP($C15,$B$3:$X$358,MATCH(W$2,$B$2:$X$2,0),0)*$G15/VLOOKUP($C15,$B$3:$X$358,MATCH($G$2,$B$2:$X$2,0),0) -> 148.90501 | X15: =VLOOKUP($C15,$B$3:$X$358,MATCH(X$2,$B$2:$X$2,0),0)*$G15/VLOOKUP($C15,$B$3:$X$358,MATCH($G$2,$B$2:$X$2,0),0) -> 0 | AI15: =$AI$11 -> 0.018362955 | AJ15: =$AJ$11 -> 0.0036561311 | AK15: =$AK$11 -> 0.0041565297 | AL15: =$AL$11 -> 0.46 | AM15: 0.00592 | AN15: =$AN$11 -> 0.00076335878 | AO15: =$AO$11 -> 0.011995638 | AP15: =$AP$11 -> 0.45761311 | AQ15: =$AQ$11 -> 0.11534667 | AS15: =$AS$11 -> 0.721765 | AT15: =$AT$228 -> 0.17824592 | AU15: =$AU$11 -> 0.43743333 | AV15: =$AV$11 -> 0.28433167 | AX15: =AI15*O15+P15*AM15 -> 0.01151933 | AY15: =$AY$11 -> 17.5728 | AZ15: 0.7 | BA15: 94.4 | BB15: 4.2 | BC15: 5.3 | BD15: 10.2 | BE15: 0 | BF15: 31.1 | BG15: 26.7 | BH15: 1036.5 | BI15: 33.4 | BJ15: 0 | BK15: 0 | BL15: 441.7 | BM15: 0 | BN15: 7.2 | BO15: 800 | BP15: 4
A16: 103 | B16: Grain, mixed | C16: Wheat | D16: Cereals, other | F16: =$F$11 -> 0.23898132 | G16: =$G$11 -> 0.87258333 | H16: =$H$11 -> 0.890375 | I16: =$I$11 -> 232.075 | J16: =$J$11 -> 873.33823 | M16: =$M$11 -> 14.911096 | N16: =$N$11 -> 15.646382 | O16: =$O$11 -> 0.45 | P16: =$P$11 -> 0.55 | Q16: =$Q$11 -> 1.2222222 | S16: =VLOOKUP(C16,$B$3:$X$358,MATCH(S$2,$B$2:$X$2,0),0) -> 1 | T16: =AI16*G16 -> 0.016023208 | U16: =VLOOKUP($C16,$B$3:$X$358,MATCH(U$2,$B$2:$X$2,0),0)*$G16/VLOOKUP($C16,$B$3:$X$358,MATCH($G$2,$B$2:$X$2,0),0) -> 11.9124 | V16: =VLOOKUP($C16,$B$3:$X$358,MATCH(V$2,$B$2:$X$2,0),0)*$G16/VLOOKUP($C16,$B$3:$X$358,MATCH($G$2,$B$2:$X$2,0),0) -> 794.16003 | W16: =VLOOKUP($C16,$B$3:$X$358,MATCH(W$2,$B$2:$X$2,0),0)*$G16/VLOOKUP($C16,$B$3:$X$358,MATCH($G$2,$B$2:$X$2,0),0) -> 148.90501 | X16: =VLOOKUP($C16,$B$3:$X$358,MATCH(X$2,$B$2:$X$2,0),0)*$G16/VLOOKUP($C16,$B$3:$X$358,MATCH($G$2,$B$2:$X$2,0),0) -> 0 | AI16: =$AI$11 -> 0.018362955 | AJ16: =$AJ$11 -> 0.0036561311 | AK16: =$AK$11 -> 0.0041565297 | AL16: =$AL$11 -> 0.46 | AM16: 0.00592 | AN16: =$AN$11 -> 0.00076335878 | AO16: =$AO$11 -> 0.011995638 | AP16: =$AP$11 -> 0.45761311 | AQ16: =$AQ$11 -> 0.11534667 | AS16: =$AS$11 -> 0.721765 | AT16: =$AT$228 -> 0.17824592 | AU16: =$AU$11 -> 0.43743333 | AV16: =$AV$11 -> 0.28433167 | AX16: =AI16*O16+P16*AM16 -> 0.01151933 | AY16: =$AY$11 -> 17.5728 | AZ16: 0.7 | BA16: 94.4 | BB16: 4.2 | BC16: 5.3 | BD16: 10.2 | BE16: 0 | BF16: 31.1 | BG16: 26.7 | BH16: 1036.5 | BI16: 33.4 | BJ16: 0 | BK16: 0 | BL16: 441.7 | BM16: 0 | BN16: 7.2 | BO16: 800 | BP16: 4
A17: OLD | B17: Oats old | C17: Oats | D17: Cereals, old | F17: 0.5553176 | G17: 0.86733333 | H17: 0.907 | I17: 232.075 | J17: 873.33823 | M17: 15.176 | N17: 15.93853 | O17: 0.33 | P17: 0.67 | Q17: 2.030303 | S17: =VLOOKUP(C17,$B$3:$X$358,MATCH(S$2,$B$2:$X$2,0),0) -> 1 | T17: =AI17*G17 -> 0.013414756 | U17: =VLOOKUP($C17,$B$3:$X$358,MATCH(U$2,$B$2:$X$2,0),0)*$G17/VLOOKUP($C17,$B$3:$X$358,MATCH($G$2,$B$2:$X$2,0),0) -> 71 | V17: =VLOOKUP($C17,$B$3:$X$358,MATCH(V$2,$B$2:$X$2,0),0)*$G17/VLOOKUP($C17,$B$3:$X$358,MATCH($G$2,$B$2:$X$2,0),0) -> 598 | W17: =VLOOKUP($C17,$B$3:$X$358,MATCH(W$2,$B$2:$X$2,0),0)*$G17/VLOOKUP($C17,$B$3:$X$358,MATCH($G$2,$B$2:$X$2,0),0) -> 796 | X17: =VLOOKUP($C17,$B$3:$X$358,MATCH(X$2,$B$2:$X$2,0),0)*$G17/VLOOKUP($C17,$B$3:$X$358,MATCH($G$2,$B$2:$X$2,0),0) -> 0 | AI17: 0.015466667 | AJ17: 0.0036666667 | AK17: 0.004 | AL17: 0.46 | AM17: =AM3 -> 0.007 | AN17: 0.00076335878 | AO17: 0.011995638 | AP17: 0.47206667 | AQ17: 0.11534667 | AS17: 0.76065 | AT17: =$AT$228 -> 0.17824592 | AU17: 0.461 | AV17: 0.29965 | AX17: =AI17*O17+P17*AM17 -> 0.009794 | AY17: 17.5728 | AZ17: 0.7 | BA17: =BA3 -> 106 | BB17: =BB3 -> 12 | BC17: =BC3 -> 22 | BD17: =BD3 -> 25 | BE17: =BE3 -> 0 | BF17: =BF3 -> 47.2 | BG17: =BG3 -> 39.7 | BH17: =BH3 -> 1770 | ... BP17: =BP3 -> 3
A18: OLD | B18: Barley old | C18: Wheat | D18: Cereals, old | F18: 0.28995426 | G18: 0.885 | H18: 0.864 | I18: 232.075 | J18: 873.33823 | M18: 15.626 | N18: 15.182899 | O18: 0.34679004 | P18: 0.65320996 | Q18: 1.8835892 | S18: =VLOOKUP(C18,$B$3:$X$358,MATCH(S$2,$B$2:$X$2,0),0) -> 1 | T18: =AI18*G18 -> 0.016480821 | U18: =VLOOKUP($C18,$B$3:$X$358,MATCH(U$2,$B$2:$X$2,0),0)*$G18/VLOOKUP($C18,$B$3:$X$358,MATCH($G$2,$B$2:$X$2,0),0) -> 12.081911 | V18: =VLOOKUP($C18,$B$3:$X$358,MATCH(V$2,$B$2:$X$2,0),0)*$G18/VLOOKUP($C18,$B$3:$X$358,MATCH($G$2,$B$2:$X$2,0),0) -> 805.46075 | W18: =VLOOKUP($C18,$B$3:$X$358,MATCH(W$2,$B$2:$X$2,0),0)*$G18/VLOOKUP($C18,$B$3:$X$358,MATCH($G$2,$B$2:$X$2,0),0) -> 151.02389 | X18: =VLOOKUP($C18,$B$3:$X$358,MATCH(X$2,$B$2:$X$2,0),0)*$G18/VLOOKUP($C18,$B$3:$X$358,MATCH($G$2,$B$2:$X$2,0),0) -> 0 | AI18: 0.018622397 | AJ18: 0.0037872787 | AK18: 0.0044569366 | AL18: 0.46 | AM18: =AM4 -> 0.007 | AN18: 0.00076335878 | AO18: 0.011995638 | AP18: 0.4467 | AQ18: 0.11534667 | AS18: 0.8085 | AT18: =$AT$228 -> 0.17824592 | AU18: 0.49 | AV18: 0.3185 | AX18: =AI18*O18+P18*AM18 -> 0.011030531 | AY18: 17.5728 | AZ18: 0.7 | BA18: =BA4 -> 148 | BB18: =BB4 -> 3 | BC18: =BC4 -> 2 | BD18: =BD4 -> 7 | BE18: =BE4 -> 0 | BF18: =BF4 -> 60 | BG18: =BG4 -> 33 | BH18: =BH4 -> 910 | ... BP18: =BP4 -> 5
A19: OLD | B19: Rice old | C19: Rice | D19: Cereals, old | F19: 0.3036 | G19: 0.864 | H19: 0.91 | I19: 232.075 | J19: 873.33823 | M19: 15.176 | N19: 15.991248 | O19: 0.3 | P19: 0.7 | Q19: 2.3333333 | S19: =VLOOKUP(C19,$B$3:$X$358,MATCH(S$2,$B$2:$X$2,0),0) -> 1 | T19: =AI19*G19 -> 0.011889908 | U19: =VLOOKUP($C19,$B$3:$X$358,MATCH(U$2,$B$2:$X$2,0),0)*$G19/VLOOKUP($C19,$B$3:$X$358,MATCH($G$2,$B$2:$X$2,0),0) -> 9 | V19: =VLOOKUP($C19,$B$3:$X$358,MATCH(V$2,$B$2:$X$2,0),0)*$G19/VLOOKUP($C19,$B$3:$X$358,MATCH($G$2,$B$2:$X$2,0),0) -> 860 | W19: =VLOOKUP($C19,$B$3:$X$358,MATCH(W$2,$B$2:$X$2,0),0)*$G19/VLOOKUP($C19,$B$3:$X$358,MATCH($G$2,$B$2:$X$2,0),0) -> 100 | X19: =VLOOKUP($C19,$B$3:$X$358,MATCH(X$2,$B$2:$X$2,0),0)*$G19/VLOOKUP($C19,$B$3:$X$358,MATCH($G$2,$B$2:$X$2,0),0) -> 0 | AI19: 0.013761468 | AJ19: 0.001146789 | AK19: 0.0013761468 | AL19: 0.46 | AM19: =AM5 -> 0.007 | AN19: 0.00076335878 | AO19: 0.011995638 | AP19: 0.40053571 | AQ19: 0.11534667 | AS19: 0.51315 | AT19: =$AT$228 -> 0.17824592 | AU19: 0.311 | AV19: 0.20215 | AX19: =AI19*O19+P19*AM19 -> 0.0090284404 | AY19: 17.5728 | AZ19: 0.7 | BA19: =BA5 -> 18.5 | BB19: =BB5 -> 2.1 | BC19: =BC5 -> 2.3 | BD19: =BD5 -> 3.2 | BE19: =BE5 -> 0 | BF19: =BF5 -> 5 | BG19: =BG5 -> 2 | BH19: =BH5 -> 130 | ... BP19: =BP5 -> 0
A20: OLD | B20: Wheat old | C20: Wheat | D20: Cereals, old | E20: 3972 | F20: 0.28070502 | G20: 0.879 | H20: 0.8665 | I20: 232.075 | J20: 873.33823 | M20: 15.226831 | N20: 15.226831 | O20: 0.28333333 | P20: 0.71666667 | Q20: 2.5294118 | S20: =VLOOKUP(C20,$B$3:$X$358,MATCH(S$2,$B$2:$X$2,0),0) -> 1 | T20: =AI20*G20 -> 0.018458825 | U20: =VLOOKUP($C20,$B$3:$X$358,MATCH(U$2,$B$2:$X$2,0),0)*$G20/VLOOKUP($C20,$B$3:$X$358,MATCH($G$2,$B$2:$X$2,0),0) -> 12 | V20: =VLOOKUP($C20,$B$3:$X$358,MATCH(V$2,$B$2:$X$2,0),0)*$G20/VLOOKUP($C20,$B$3:$X$358,MATCH($G$2,$B$2:$X$2,0),0) -> 800 | W20: =VLOOKUP($C20,$B$3:$X$358,MATCH(W$2,$B$2:$X$2,0),0)*$G20/VLOOKUP($C20,$B$3:$X$358,MATCH($G$2,$B$2:$X$2,0),0) -> 150 | X20: =VLOOKUP($C20,$B$3:$X$358,MATCH(X$2,$B$2:$X$2,0),0)*$G20/VLOOKUP($C20,$B$3:$X$358,MATCH($G$2,$B$2:$X$2,0),0) -> 0 | AI20: 0.020999801 | AJ20: 0.003514448 | AK20: 0.0040126526 | AL20: 0.46 | AM20: =AM9 -> 0.00592 | AN20: 0.00076335878 | AO20: 0.011995638 | AP20: 0.4579975 | AQ20: 0.11534667 | AS20: 0.7656 | AT20: =$AT$228 -> 0.17824592 | AU20: 0.464 | AV20: 0.3016 | AX20: =AI20*O20+P20*AM20 -> 0.01019261 | AY20: 17.5728 | AZ20: 0.7 | BA20: =BA9 -> 10 | BB20: =BB6 -> 6.1 | BC20: =BC6 -> 9.8 | BD20: =BD6 -> 17.5 | BE20: =BE6 -> 0 | BF20: =BF6 -> 39 | BG20: =BG6 -> 30 | BH20: =BH6 -> 1300 | BI20: =BI6 -> 33.4 | ... BP20: =BP6 -> 3
A21: OLD | B21: Maize old | C21: Maize | D21: Cereals, old | F21: 0.33541564 | G21: 0.862 | H21: 0.881 | I21: 232.075 | J21: 873.33823 | M21: 14.4384 | N21: 15.481637 | O21: 0.45 | P21: 0.55 | Q21: 1.2222222 | S21: =VLOOKUP(C21,$B$3:$X$358,MATCH(S$2,$B$2:$X$2,0),0) -> 1 | T21: =AI21*G21 -> 0.01248 | U21: =VLOOKUP($C21,$B$3:$X$358,MATCH(U$2,$B$2:$X$2,0),0)*$G21/VLOOKUP($C21,$B$3:$X$358,MATCH($G$2,$B$2:$X$2,0),0) -> 27 | V21: =VLOOKUP($C21,$B$3:$X$358,MATCH(V$2,$B$2:$X$2,0),0)*$G21/VLOOKUP($C21,$B$3:$X$358,MATCH($G$2,$B$2:$X$2,0),0) -> 760 | W21: =VLOOKUP($C21,$B$3:$X$358,MATCH(W$2,$B$2:$X$2,0),0)*$G21/VLOOKUP($C21,$B$3:$X$358,MATCH($G$2,$B$2:$X$2,0),0) -> 120 | X21: =VLOOKUP($C21,$B$3:$X$358,MATCH(X$2,$B$2:$X$2,0),0)*$G21/VLOOKUP($C21,$B$3:$X$358,MATCH($G$2,$B$2:$X$2,0),0) -> 0 | AI21: 0.014477958 | AJ21: 0.003062645 | AK21: 0.0036426914 | AL21: 0.44 | AM21: =AM10 -> 0.00592 | AN21: 0.00076335878 | AO21: 0.011995638 | AP21: 0.43383889 | AQ21: 0.11534667 | AS21: 0.6798 | AT21: =$AT$228 -> 0.17824592 | AU21: 0.412 | AV21: 0.2678 | AX21: =AI21*O21+P21*AM21 -> 0.0097710812 | AY21: 17.5728 | AZ21: 0.7 | BA21: =BA10 -> 27 | BB21: =BB7 -> 2.9 | BC21: =BC7 -> 3 | BD21: =BD7 -> 11 | BE21: =BE7 -> 0 | BF21: =BF7 -> 26.7 | BG21: =BG7 -> 37.3 | BH21: =BH7 -> 1210 | BI21: =BI7 -> 33.4 | ... BP21: =BP7 -> 3.5
B22: Straw | D22: Cereal residues | G22: =H12 -> 0.8755 | AI22: =AM11 -> 0.00592 | AJ22: =AN11 -> 0.00076335878 | AK22: =AO11 -> 0.011995638 | AX22: =AI22*O22+P22*AM22 -> 0 | AZ22: 0.7
B23: Other crop residues | D23: Other residues | G23: =H33 -> 0.89966667 | AI23: =AM33 -> 0.008 | AJ23: =AN33 -> 0.00077777778 | AK23: =AO33 -> 0.015 | AX23: =AI23*O23+P23*AM23 -> 0 | AZ23: 0.7
A24: 242 | B24: Groundnuts, with shell | D24: Oilseeds | F24: 0.07 | G24: 0.91616667 | H24: 0.89966667 | I24: 232.075 | J24: 873.33823 | M24: 15.809662 | N24: 15.809662 | O24: 0.330033 | P24: 0.669967 | Q24: 2.03 | S24: 0.7 | T24: =VLOOKUP($B24,Conversores_Dieta!$B$4:$J$164,Coefs!T$292,0) -> 0.0432 | U24: =VLOOKUP($B24,Conversores_Dieta!$B$4:$J$164,Coefs!U$292,0) -> 490 | V24: =VLOOKUP($B24,Conversores_Dieta!$B$4:$J$164,Coefs!V$292,0) -> 85 | W24: =VLOOKUP($B24,Conversores_Dieta!$B$4:$J$164,Coefs!W$292,0) -> 610 | X24: =VLOOKUP($B24,Conversores_Dieta!$B$4:$J$164,Coefs!X$292,0) -> 0 | AI24: =T24/G24 -> 0.047152993 | AJ24: 0.0049991946 | AK24: 0.012371095 | AL24: 0.6 | AM24: 0.016 | AN24: 0.00077777778 | AO24: 0.015 | AP24: 0.43749765 | AQ24: 0.11534667 | AS24: 0.74707045 | AT24: =$AT$228 -> 0.17824592 | AU24: 0.45276997 | AV24: 0.29430048 | AX24: =AI24*O24+P24*AM24 -> 0.026281516 | AY24: 17.5728 | AZ24: 0.7 | BA24: 81 | BB24: 67.5 | BC24: 231.4 | BD24: 131.9 | BE24: 0.4 | BF24: 25 | BG24: 35 | BH24: 2100 | BI24: 36.2 | BJ24: 0 | BK24: 0 | BL24: 1100 | BM24: 0 | BN24: 109.4 | BO24: 2 | BP24: 0.5
A25: 191 | B25: Chickpea | D25: Legumes | F25: 0.08 | G25: 0.944 | H25: 0.893 | I25: 232.075 | J25: 873.33823 | M25: 15.762 | N25: 15.69251 | O25: 0.37037037 | P25: 0.62962963 | Q25: 1.7 | S25: =VLOOKUP($B25,Conversores_Dieta!$B$4:$J$164,Coefs!S$292,0) -> 1 | T25: =VLOOKUP($B25,Conversores_Dieta!$B$4:$J$164,Coefs!T$292,0) -> 0.03104 | U25: =VLOOKUP($B25,Conversores_Dieta!$B$4:$J$164,Coefs!U$292,0) -> 50 | V25: =VLOOKUP($B25,Conversores_Dieta!$B$4:$J$164,Coefs!V$292,0) -> 550 | W25: =VLOOKUP($B25,Conversores_Dieta!$B$4:$J$164,Coefs!W$292,0) -> 1450 | X25: =VLOOKUP($B25,Conversores_Dieta!$B$4:$J$164,Coefs!X$292,0) -> 320 | AI25: =T25/G25 -> 0.032881356 | AJ25: 0.0049991946 | AK25: 0.012371095 | AL25: 0.46 | AM25: 0.0092 | AN25: 0.00077777778 | AO25: 0.015 | AP25: 0.44 | AQ25: 0.11534667 | AS25: 0.6971831 | AT25: =$AT$228 -> 0.17824592 | AU25: 0.42253521 | AV25: 0.27464789 | AX25: =AI25*O25+P25*AM25 -> 0.017970873 | AY25: 17.5728 | AZ25: 0.7 | BA25: 149.7 | BB25: 4.3 | BC25: 18 | BD25: 28.1 | BE25: 0 | BF25: 68 | BG25: 20 | BH25: 1220 | BI25: 4.39 | BJ25: 0 | BK25: 0 | BL25: 1850 | BM25: 41 | BN25: 31 | BO25: 225 | BP25: 1.5
A26: 236 | B26: Soyabeans | C26: Beans | D26: Oilseeds | E26: 3330.8333 | F26: 0.38854428 | G26: 0.86 | H26: 0.88566667 | I26: 232.075 | J26: 873.33823 | M26: 18.197 | N26: 15.563643 | O26: 0.349316 | P26: 0.650684 | Q26: 1.8627375 | S26: =VLOOKUP(C26,$B$3:$X$358,MATCH(S$2,$B$2:$X$2,0),0) -> 1 | T26: 0.0608 | U26: =VLOOKUP($C26,$B$3:$X$358,MATCH(U$2,$B$2:$X$2,0),0)*$G26/VLOOKUP($C26,$B$3:$X$358,MATCH($G$2,$B$2:$X$2,0),0) -> 12.24822 | V26: =VLOOKUP($C26,$B$3:$X$358,MATCH(V$2,$B$2:$X$2,0),0)*$G26/VLOOKUP($C26,$B$3:$X$358,MATCH($G$2,$B$2:$X$2,0),0) -> 459.30824 | W26: =VLOOKUP($C26,$B$3:$X$358,MATCH(W$2,$B$2:$X$2,0),0)*$G26/VLOOKUP($C26,$B$3:$X$358,MATCH($G$2,$B$2:$X$2,0),0) -> 113.73347 | X26: =VLOOKUP($C26,$B$3:$X$358,MATCH(X$2,$B$2:$X$2,0),0)*$G26/VLOOKUP($C26,$B$3:$X$358,MATCH($G$2,$B$2:$X$2,0),0) -> 0 | AI26: =T26/G26 -> 0.070697674 | AJ26: 0.0062291435 | AK26: 0.0189099 | AL26: 0.52 | AM26: 0.008 | AN26: 0.00077777778 | AO26: 0.015 | AP26: 0.43116667 | AQ26: 0.11534667 | AS26: 0.766425 | AT26: =$AT$228 -> 0.17824592 | AU26: 0.4645 | AV26: 0.301925 | AX26: =AI26*O26+P26*AM26 -> 0.029901301 | AY26: 17.5728 | AZ26: 0.7 | BA26: 42 | BB26: 7.9 | BC26: 13 | BD26: 32 | BE26: 13.5 | BF26: 35.5 | BG26: 9.9 | BH26: 650 | BI26: 4.49 | BJ26: 0 | BK26: 0 | BL26: 1650 | BM26: 290 | BN26: 1 | BO26: 1000 | BP26: 15
A27: 201 | B27: Lentils | D27: Legumes | F27: 0.2879694 | G27: 0.8965 | H27: 0.928 | I27: 232.075 | J27: 873.33823 | M27: 15.356 | N27: 16.307558 | O27: 0.32467532 | P27: 0.67532468 | Q27: 2.08 | S27: =VLOOKUP($B27,Conversores_Dieta!$B$4:$J$164,Coefs!S$292,0) -> 1 | T27: =VLOOKUP($B27,Conversores_Dieta!$B$4:$J$164,Coefs!T$292,0) -> 0.03808 | U27: =VLOOKUP($B27,Conversores_Dieta!$B$4:$J$164,Coefs!U$292,0) -> 18 | V27: =VLOOKUP($B27,Conversores_Dieta!$B$4:$J$164,Coefs!V$292,0) -> 540 | W27: =VLOOKUP($B27,Conversores_Dieta!$B$4:$J$164,Coefs!W$292,0) -> 560 | X27: =VLOOKUP($B27,Conversores_Dieta!$B$4:$J$164,Coefs!X$292,0) -> 100 | AI27: =T27/G27 -> 0.042476297 | AJ27: 0.0046590909 | AK27: 0.010454545 | AL27: 0.46 | AM27: 0.0127 | AN27: 0.00077777778 | AO27: 0.015 | AP27: 0.415 | AQ27: 0.11534667 | AS27: 0.69899666 | AT27: =$AT$228 -> 0.17824592 | AU27: 0.42363434 | AV27: 0.27536232 | AX27: =AI27*O27+P27*AM27 -> 0.022367629 | AY27: 17.5728 | AZ27: 0.7 | BA27: 97 | BB27: 1.7 | BC27: 2.2 | BD27: 5.5 | BE27: 0 | BF27: 68.7 | BG27: 39 | BH27: 743.2 | BI27: 4.39 | BJ27: 0 | BK27: 0 | BL27: 1171 | BM27: 17 | BN27: 9 | BO27: 275 | BP27: 0.8
A28: 210 | B28: Lupin | C28: Lentils | D28: Legumes | F28: 0.2879694 | G28: 0.91616667 | H28: 0.89966667 | I28: 232.075 | J28: 873.33823 | M28: 15.809662 | N28: 15.809662 | O28: 0.3003003 | P28: 0.6996997 | Q28: 2.33 | S28: =VLOOKUP(C28,$B$3:$X$358,MATCH(S$2,$B$2:$X$2,0),0) -> 1 | T28: =VLOOKUP($C28,$B$3:$X$358,MATCH(T$2,$B$2:$X$2,0),0)*$G28/VLOOKUP($C28,$B$3:$X$358,MATCH($G$2,$B$2:$X$2,0),0) -> 0.038915367 | U28: =VLOOKUP($C28,$B$3:$X$358,MATCH(U$2,$B$2:$X$2,0),0)*$G28/VLOOKUP($C28,$B$3:$X$358,MATCH($G$2,$B$2:$X$2,0),0) -> 18.394869 | V28: =VLOOKUP($C28,$B$3:$X$358,MATCH(V$2,$B$2:$X$2,0),0)*$G28/VLOOKUP($C28,$B$3:$X$358,MATCH($G$2,$B$2:$X$2,0),0) -> 551.84607 | W28: =VLOOKUP($C28,$B$3:$X$358,MATCH(W$2,$B$2:$X$2,0),0)*$G28/VLOOKUP($C28,$B$3:$X$358,MATCH($G$2,$B$2:$X$2,0),0) -> 572.28481 | X28: =VLOOKUP($C28,$B$3:$X$358,MATCH(X$2,$B$2:$X$2,0),0)*$G28/VLOOKUP($C28,$B$3:$X$358,MATCH($G$2,$B$2:$X$2,0),0) -> 102.19372 | AI28: 0.053450937 | AJ28: 0.0038588754 | AK28: 0.0093715546 | AL28: 0.47444444 | AM28: 0.008 | AN28: 0.00077777778 | AO28: 0.015 | AP28: 0.477 | AQ28: 0.11534667 | AS28: 0.80355 | AT28: =$AT$228 -> 0.17824592 | AU28: 0.487 | AV28: 0.31655 | AX28: =AI28*O28+P28*AM28 -> 0.02164893 | AY28: 17.5728 | AZ28: 0.7 | BA28: 165 | BB28: 4 | BC28: 22 | BD28: 24 | BE28: 0 | BF28: 43.6 | BG28: 47.5 | BH28: 1980 | BI28: 4.39 | BJ28: 0 | BK28: 0 | BL28: 3550 | BM28: 0 | BN28: 6 | BO28: 375 | BP28: 3
A29: 187 | B29: Pea | D29: Legumes | F29: 0.08 | G29: 0.91616667 | H29: 0.89966667 | I29: 232.075 | J29: 873.33823 | M29: 15.385 | N29: 15.809662 | O29: 0.36832077 | P29: 0.63167923 | Q29: 1.7150247 | S29: =VLOOKUP($B29,Conversores_Dieta!$B$4:$J$164,Coefs!S$292,0) -> 1 | T29: =VLOOKUP($B29,Conversores_Dieta!$B$4:$J$164,Coefs!T$292,0) -> 0.03456 | U29: =VLOOKUP($B29,Conversores_Dieta!$B$4:$J$164,Coefs!U$292,0) -> 23 | V29: =VLOOKUP($B29,Conversores_Dieta!$B$4:$J$164,Coefs!V$292,0) -> 560 | W29: =VLOOKUP($B29,Conversores_Dieta!$B$4:$J$164,Coefs!W$292,0) -> 720 | X29: =VLOOKUP($B29,Conversores_Dieta!$B$4:$J$164,Coefs!X$292,0) -> 420 | AI29: 0.037412032 | AJ29: 0.0045402951 | AK29: 0.011918275 | AL29: 0.46 | AM29: 0.008 | AN29: 0.00077777778 | AO29: 0.015 | AP29: 0.457 | AQ29: 0.11534667 | AS29: 0.73213837 | AT29: =$AT$228 -> 0.17824592 | AU29: 0.44372023 | AV29: 0.28841815 | AX29: =AI29*O29+P29*AM29 -> 0.018833062 | AY29: 17.5728 | AZ29: 0.7 | BA29: 167 | BB29: 1.5 | BC29: 1.3 | BD29: 0.5 | BE29: 0 | BF29: 15 | BG29: 35 | BH29: 1230 | BI29: 4.49 | BJ29: 0 | BK29: 0 | BL29: 780 | BM29: 180 | BN29: 1 | BO29: 175 | BP29: 4.5
A30: 181 | B30: Fava bean | D30: Legumes | F30: 0.60333333 | G30: 0.91533333 | H30: 0.886 | I30: 232.075 | J30: 873.33823 | M30: 15.809662 | N30: 15.809662 | O30: 0.39024422 | P30: 0.60975578 | Q30: 1.5624979 | S30: =VLOOKUP($B30,Conversores_Dieta!$B$4:$J$164,Coefs!S$292,0) -> 1 | T30: =VLOOKUP($B30,Conversores_Dieta!$B$4:$J$164,Coefs!T$292,0) -> 0.0368 | U30: =VLOOKUP($B30,Conversores_Dieta!$B$4:$J$164,Coefs!U$292,0) -> 20 | V30: =VLOOKUP($B30,Conversores_Dieta!$B$4:$J$164,Coefs!V$292,0) -> 560 | W30: =VLOOKUP($B30,Conversores_Dieta!$B$4:$J$164,Coefs!W$292,0) -> 1150 | X30: =VLOOKUP($B30,Conversores_Dieta!$B$4:$J$164,Coefs!X$292,0) -> 420 | AI30: 0.044200913 | AJ30: 0.0057077626 | AK30: 0.013127854 | AL30: 0.46 | AM30: 0.008 | AN30: 0.0015 | AO30: 0.015 | AP30: 0.43749765 | AQ30: 0.11534667 | AS30: 0.72602959 | AT30: =$AT$228 -> 0.17824592 | AU30: 0.44001793 | AV30: 0.28601166 | AX30: =AI30*O30+P30*AM30 -> 0.022127197 | AY30: 17.843863 | AZ30: 0.7 | BA30: 42 | BB30: 0.5 | BC30: 0.4 | BD30: 2 | BE30: 0 | BF30: 17 | BG30: 7 | BH30: 280 | BI30: 4.39 | BJ30: 0 | BK30: 0 | BL30: 780 | BM30: 240 | BN30: 0 | BO30: 175 | BP30: 2
A31: 205 | B31: Vetch | C31: Lentils | D31: Legumes | F31: 0.2879694 | G31: 0.9 | H31: 0.911 | I31: 232.075 | J31: 873.33823 | M31: 18.751433 | N31: 16.008821 | O31: 0.44576523 | P31: 0.55423477 | Q31: 1.2433333 | S31: =VLOOKUP(C31,$B$3:$X$358,MATCH(S$2,$B$2:$X$2,0),0) -> 1 | T31: =VLOOKUP($C31,$B$3:$X$358,MATCH(T$2,$B$2:$X$2,0),0)*$G31/VLOOKUP($C31,$B$3:$X$358,MATCH($G$2,$B$2:$X$2,0),0) -> 0.038228667 | U31: =VLOOKUP($C31,$B$3:$X$358,MATCH(U$2,$B$2:$X$2,0),0)*$G31/VLOOKUP($C31,$B$3:$X$358,MATCH($G$2,$B$2:$X$2,0),0) -> 18.070273 | V31: =VLOOKUP($C31,$B$3:$X$358,MATCH(V$2,$B$2:$X$2,0),0)*$G31/VLOOKUP($C31,$B$3:$X$358,MATCH($G$2,$B$2:$X$2,0),0) -> 542.1082 | W31: =VLOOKUP($C31,$B$3:$X$358,MATCH(W$2,$B$2:$X$2,0),0)*$G31/VLOOKUP($C31,$B$3:$X$358,MATCH($G$2,$B$2:$X$2,0),0) -> 562.18628 | X31: =VLOOKUP($C31,$B$3:$X$358,MATCH(X$2,$B$2:$X$2,0),0)*$G31/VLOOKUP($C31,$B$3:$X$358,MATCH($G$2,$B$2:$X$2,0),0) -> 100.39041 | AI31: 0.037333333 | AJ31: 0.005 | AK31: 0.010444444 | AL31: 0.44 | AM31: 0.008 | AN31: 0.00077777778 | AO31: 0.015 | AP31: 0.43876948 | AQ31: 0.11534667 | AS31: 0.77385 | AT31: =$AT$228 -> 0.17824592 | AU31: 0.469 | AV31: 0.30485 | AX31: =AI31*O31+P31*AM31 -> 0.02107578 | AY31: 17.5728 | AZ31: 0.7 | BA31: 130 | BB31: 0 | BC31: 0 | BD31: 0 | BE31: 0 | BF31: 0 | BG31: 25 | BH31: 740 | BI31: 4.49 | BJ31: 0 | BK31: 0 | BL31: 0 | BM31: 0 | BN31: 0 | BO31: 300 | BP31: 2.5
A32: 176 | B32: Beans | D32: Legumes | F32: 0.2879694 | G32: 0.983 | H32: 0.871 | I32: 232.075 | J32: 873.33823 | M32: 15.809662 | N32: 15.809662 | O32: 0.36832077 | P32: 0.63167923 | Q32: 1.7150247 | S32: =VLOOKUP($B32,Conversores_Dieta!$B$4:$J$164,Coefs!S$292,0) -> 1 | T32: =VLOOKUP($B32,Conversores_Dieta!$B$4:$J$164,Coefs!T$292,0) -> 0.0304 | U32: =VLOOKUP($B32,Conversores_Dieta!$B$4:$J$164,Coefs!U$292,0) -> 14 | V32: =VLOOKUP($B32,Conversores_Dieta!$B$4:$J$164,Coefs!V$292,0) -> 525 | W32: =VLOOKUP($B32,Conversores_Dieta!$B$4:$J$164,Coefs!W$292,0) -> 130 | X32: =VLOOKUP($B32,Conversores_Dieta!$B$4:$J$164,Coefs!X$292,0) -> 0 | AI32: =T32/G32 -> 0.030925738 | AJ32: 0.0049991946 | AK32: 0.012371095 | AL32: 0.46 | AM32: 0.008 | AN32: 0.0014 | AO32: 0.0114 | AP32: 0.43635 | AQ32: 0.11534667 | AS32: 0.75735 | AT32: =$AT$228 -> 0.17824592 | AU32: 0.459 | AV32: 0.29835 | AX32: =AI32*O32+P32*AM32 -> 0.016444025 | AY32: 18.151162 | AZ32: 0.7 | BA32: 44 | BB32: 2.8 | BC32: 1 | BD32: 7 | BE32: 0 | BF32: 51.9 | BG32: 23 | BH32: 390 | BI32: 4.49 | BJ32: 0 | BK32: 0 | BL32: 3080 | BM32: 0 | BN32: 0.5 | BO32: 200 | BP32: 2
A33: 211 | B33: Pulses nes | C33: Pea | D33: Legumes | F33: 0.2879694 | G33: 0.91616667 | H33: 0.89966667 | I33: 232.075 | J33: 873.33823 | M33: 15.809662 | N33: 15.809662 | O33: 0.36832077 | P33: 0.63167923 | Q33: 1.7150247 | S33: =VLOOKUP(C33,$B$3:$X$358,MATCH(S$2,$B$2:$X$2,0),0) -> 1 | T33: =VLOOKUP($C33,$B$3:$X$358,MATCH(T$2,$B$2:$X$2,0),0)*$G33/VLOOKUP($C33,$B$3:$X$358,MATCH($G$2,$B$2:$X$2,0),0) -> 0.03456 | U33: =VLOOKUP($C33,$B$3:$X$358,MATCH(U$2,$B$2:$X$2,0),0)*$G33/VLOOKUP($C33,$B$3:$X$358,MATCH($G$2,$B$2:$X$2,0),0) -> 23 | V33: =VLOOKUP($C33,$B$3:$X$358,MATCH(V$2,$B$2:$X$2,0),0)*$G33/VLOOKUP($C33,$B$3:$X$358,MATCH($G$2,$B$2:$X$2,0),0) -> 560 | W33: =VLOOKUP($C33,$B$3:$X$358,MATCH(W$2,$B$2:$X$2,0),0)*$G33/VLOOKUP($C33,$B$3:$X$358,MATCH($G$2,$B$2:$X$2,0),0) -> 720 | X33: =VLOOKUP($C33,$B$3:$X$358,MATCH(X$2,$B$2:$X$2,0),0)*$G33/VLOOKUP($C33,$B$3:$X$358,MATCH($G$2,$B$2:$X$2,0),0) -> 420 | AI33: 0.047042641 | AJ33: 0.0049991946 | AK33: 0.012371095 | AL33: 0.47444444 | AM33: 0.008 | AN33: 0.00077777778 | AO33: 0.015 | AP33: 0.43749765 | AQ33: 0.11534667 | AS33: 0.74707045 | AT33: =$AT$228 -> 0.17824592 | AU33: 0.45276997 | AV33: 0.29430048 | AX33: =AI33*O33+P33*AM33 -> 0.022380216 | AY33: 17.5728 | AZ33: 0.7 | BA33: 85.8 | BB33: 3.3 | BC33: 10.9 | BD33: 16.6 | BE33: 0 | BF33: 62.3 | BG33: 28.1 | BH33: 941.9 | BI33: 4.49 | BJ33: 0 | BK33: 0 | BL33: 2607.8 | BM33: 74.5 | BN33: 11.6 | BO33: 300 | BP33: 3.3
B34: Tigernuts | D34: Roots and tubers | F34: 0.041176471 | G34: 0.30033333 | H34: 0.25 | I34: 232.075 | J34: 873.33823 | K34: 3.939 | L34: 4.261404 | M34: 4.966349 | N34: 3.51456 | O34: 0.5 | P34: 0.5 | Q34: 1 | S34: =VLOOKUP($B34,Conversores_Dieta!$B$4:$J$164,Coefs!S$292,0) -> 1 | T34: =VLOOKUP($B34,Conversores_Dieta!$B$4:$J$164,Coefs!T$292,0) -> 0.00976 | U34: =VLOOKUP($B34,Conversores_Dieta!$B$4:$J$164,Coefs!U$292,0) -> 237 | V34: =VLOOKUP($B34,Conversores_Dieta!$B$4:$J$164,Coefs!V$292,0) -> 425 | W34: =VLOOKUP($B34,Conversores_Dieta!$B$4:$J$164,Coefs!W$292,0) -> 700 | X34: =VLOOKUP($B34,Conversores_Dieta!$B$4:$J$164,Coefs!X$292,0) -> 0 | AI34: 0.0087991128 | AJ34: 0.0016558783 | AK34: 0.013525658 | AL34: 0.42 | AM34: 0.019 | AP34: 0.43689436 | AQ34: 0.11534667 | AS34: 0.72602959 | AT34: =$AT$228 -> 0.17824592 | AU34: 0.44001793 | AV34: 0.28601166 | AX34: =AI34*O34+P34*AM34 -> 0.013899556 | AY34: 14.05824 | AZ34: 0.7 | BA34: =BA38 -> 0 | BB34: =BB38 -> 0 | BC34: =BC38 -> 0 | BD34: =BD38 -> 0 | BE34: =BE38 -> 0.3 | BF34: =BF38 -> 6 | BG34: =BG38 -> 4 | BH34: =BH38 -> 350 | ... BP34: =BP38 -> 15
A35: 122 | B35: Sweet potato | D35: Roots and tubers | F35: 0.041176471 | G35: 0.258 | H35: 0.25 | I35: 232.075 | J35: 873.33823 | K35: 4.165 | L35: 4.5337824 | M35: 4.2424443 | N35: 3.51456 | O35: 0.53000069 | P35: 0.46999931 | Q35: 0.88679 | S35: =VLOOKUP($B35,Conversores_Dieta!$B$4:$J$164,Coefs!S$292,0) -> 0.79 | T35: =VLOOKUP($B35,Conversores_Dieta!$B$4:$J$164,Coefs!T$292,0) -> 0.00192 | U35: =VLOOKUP($B35,Conversores_Dieta!$B$4:$J$164,Coefs!U$292,0) -> 6 | V35: =VLOOKUP($B35,Conversores_Dieta!$B$4:$J$164,Coefs!V$292,0) -> 215 | W35: =VLOOKUP($B35,Conversores_Dieta!$B$4:$J$164,Coefs!W$292,0) -> 220 | X35: =VLOOKUP($B35,Conversores_Dieta!$B$4:$J$164,Coefs!X$292,0) -> 6670 | AI35: 0.006 | AJ35: 0.0015909091 | AK35: 0.0073863636 | AL35: 0.41 | AM35: 0.019 | AN35: 0 | AO35: 0 | AP35: 0.43689436 | AQ35: 0.11534667 | AS35: 0.72602959 | AT35: =$AT$228 -> 0.17824592 | AU35: 0.44001793 | AV35: 0.28601166 | AX35: =AI35*O35+P35*AM35 -> 0.012109991 | AY35: 14.05824 | AZ35: 0.7 | BA35: 29 | BB35: 0 | BC35: 0 | BD35: 1.3 | BE35: 0.5 | BF35: 7 | BG35: 3 | BH35: 130 | BI35: 21.7 | BJ35: 0 | BK35: 0 | BL35: 520 | BM35: 250 | BN35: 40 | BO35: 175 | BP35: 10
A36: 116 | B36: Potato | D36: Roots and tubers | F36: 0.041176471 | G36: 0.227 | H36: 0.2 | I36: 232.075 | J36: 873.33823 | K36: 3.713 | L36: 3.9890256 | M36: 3.7406026 | N36: 3.51456 | O36: 0.58823529 | P36: 0.41176471 | Q36: 0.7 | S36: =VLOOKUP($B36,Conversores_Dieta!$B$4:$J$164,Coefs!S$292,0) -> 0.9 | T36: =VLOOKUP($B36,Conversores_Dieta!$B$4:$J$164,Coefs!T$292,0) -> 0.004 | U36: =VLOOKUP($B36,Conversores_Dieta!$B$4:$J$164,Coefs!U$292,0) -> 2 | V36: =VLOOKUP($B36,Conversores_Dieta!$B$4:$J$164,Coefs!V$292,0) -> 180 | W36: =VLOOKUP($B36,Conversores_Dieta!$B$4:$J$164,Coefs!W$292,0) -> 90 | X36: =VLOOKUP($B36,Conversores_Dieta!$B$4:$J$164,Coefs!X$292,0) -> 0 | AI36: 0.016 | AJ36: 0.002247191 | AK36: 0.024719101 | AL36: 0.41 | AM36: 0.019 | AP36: 0.4305 | AQ36: 0.11534667 | AS36: 0.72602959 | AT36: =$AT$228 -> 0.17824592 | AU36: 0.44001793 | AV36: 0.28601166 | AX36: =AI36*O36+P36*AM36 -> 0.017235294 | AY36: 17.5728 | AZ36: 0.7 | BA36: 17 | BB36: 0.3 | BC36: 0 | BD36: 1.1 | BE36: 0.5 | BF36: 7 | BG36: 4 | BH36: 200 | BI36: 21.7 | BJ36: 0 | BK36: 0 | BL36: 160 | BM36: 190 | BN36: 0.6 | BO36: 150 | BP36: 7.5
B37: Cassava | C37: Potato | D37: Roots and tubers | F37: 0.041176471 | G37: 0.416 | H37: 0.3 | I37: 232.075 | J37: 873.33823 | K37: 3.939 | L37: 4.261404 | M37: 6.916 | N37: 3.51456 | O37: 0.53941199 | P37: 0.46058801 | Q37: 0.86226333 | S37: =VLOOKUP(C37,$B$3:$X$358,MATCH(S$2,$B$2:$X$2,0),0) -> 0.9 | T37: 0.00144 | U37: =VLOOKUP($C37,$B$3:$X$358,MATCH(U$2,$B$2:$X$2,0),0)*$G37/VLOOKUP($C37,$B$3:$X$358,MATCH($G$2,$B$2:$X$2,0),0) -> 3.6651982 | V37: =VLOOKUP($C37,$B$3:$X$358,MATCH(V$2,$B$2:$X$2,0),0)*$G37/VLOOKUP($C37,$B$3:$X$358,MATCH($G$2,$B$2:$X$2,0),0) -> 329.86784 | W37: =VLOOKUP($C37,$B$3:$X$358,MATCH(W$2,$B$2:$X$2,0),0)*$G37/VLOOKUP($C37,$B$3:$X$358,MATCH($G$2,$B$2:$X$2,0),0) -> 164.93392 | X37: =VLOOKUP($C37,$B$3:$X$358,MATCH(X$2,$B$2:$X$2,0),0)*$G37/VLOOKUP($C37,$B$3:$X$358,MATCH($G$2,$B$2:$X$2,0),0) -> 0 | AI37: =T37/G37 -> 0.0034615385 | AJ37: 0.0011295347 | AK37: 0.0084715102 | AL37: 0.44 | AM37: 0.019 | AP37: 0.43689436 | AQ37: 0.11534667 | AS37: 0.72602959 | AT37: =$AT$228 -> 0.17824592 | AU37: 0.44001793 | AV37: 0.28601166 | AX37: =AI37*O37+P37*AM37 -> 0.010618367 | AY37: 11.7152 | AZ37: 0.7 | BA37: =BA38 -> 0 | BB37: =BB38 -> 0 | BC37: =BC38 -> 0 | BD37: =BD38 -> 0 | BE37: =BE38 -> 0.3 | BF37: =BF38 -> 6 | BG37: =BG38 -> 4 | BH37: =BH38 -> 350 | ... BP37: =BP38 -> 15
A38: 149 | B38: Roots, other | C38: Potato | D38: Roots and tubers | F38: 0.041176471 | G38: 0.30033333 | H38: 0.25 | I38: 232.075 | J38: 873.33823 | K38: 3.939 | L38: 4.261404 | M38: 4.966349 | N38: 3.51456 | O38: 0.53941199 | P38: 0.46058801 | Q38: 0.86226333 | S38: =VLOOKUP(C38,$B$3:$X$358,MATCH(S$2,$B$2:$X$2,0),0) -> 0.9 | T38: =VLOOKUP($C38,$B$3:$X$358,MATCH(T$2,$B$2:$X$2,0),0)*$G38/VLOOKUP($C38,$B$3:$X$358,MATCH($G$2,$B$2:$X$2,0),0) -> 0.0052922173 | U38: =VLOOKUP($C38,$B$3:$X$358,MATCH(U$2,$B$2:$X$2,0),0)*$G38/VLOOKUP($C38,$B$3:$X$358,MATCH($G$2,$B$2:$X$2,0),0) -> 2.6461087 | V38: =VLOOKUP($C38,$B$3:$X$358,MATCH(V$2,$B$2:$X$2,0),0)*$G38/VLOOKUP($C38,$B$3:$X$358,MATCH($G$2,$B$2:$X$2,0),0) -> 238.14978 | W38: =VLOOKUP($C38,$B$3:$X$358,MATCH(W$2,$B$2:$X$2,0),0)*$G38/VLOOKUP($C38,$B$3:$X$358,MATCH($G$2,$B$2:$X$2,0),0) -> 119.07489 | X38: =VLOOKUP($C38,$B$3:$X$358,MATCH(X$2,$B$2:$X$2,0),0)*$G38/VLOOKUP($C38,$B$3:$X$358,MATCH($G$2,$B$2:$X$2,0),0) -> 0 | AI38: 0.0087991128 | AJ38: 0.0016558783 | AK38: 0.013525658 | AL38: 0.42 | AM38: 0.019 | AP38: 0.4305 | AQ38: 0.11534667 | AS38: 0.72602959 | AT38: =$AT$228 -> 0.17824592 | AU38: 0.44001793 | AV38: 0.28601166 | AX38: =AI38*O38+P38*AM38 -> 0.013497519 | AY38: 14.05824 | AZ38: 0.7 | BA38: 0 | BB38: 0 | BC38: 0 | BD38: 0 | BE38: 0.3 | BF38: 6 | BG38: 4 | BH38: 350 | BI38: 14.1 | BJ38: 0 | BK38: 0 | BL38: 0 | BM38: 40 | BN38: 0 | BO38: 150 | BP38: 15
B39: Roots, dry equivalent | C39: Potato | F39: 0.041176471 | G39: 1 | H39: 1 | I39: 232.075 | J39: 873.33823 | K39: 3.939 | L39: 4.261404 | M39: 16.536123 | N39: 14.05824 | O39: 0.53941199 | P39: 0.46058801 | Q39: 0.86226333 | S39: =VLOOKUP(C39,$B$3:$X$358,MATCH(S$2,$B$2:$X$2,0),0) -> 0.9 | T39: =VLOOKUP($C39,$B$3:$X$358,MATCH(T$2,$B$2:$X$2,0),0)*$G39/VLOOKUP($C39,$B$3:$X$358,MATCH($G$2,$B$2:$X$2,0),0) -> 0.017621145 | U39: =VLOOKUP($C39,$B$3:$X$358,MATCH(U$2,$B$2:$X$2,0),0)*$G39/VLOOKUP($C39,$B$3:$X$358,MATCH($G$2,$B$2:$X$2,0),0) -> 8.8105727 | V39: =VLOOKUP($C39,$B$3:$X$358,MATCH(V$2,$B$2:$X$2,0),0)*$G39/VLOOKUP($C39,$B$3:$X$358,MATCH($G$2,$B$2:$X$2,0),0) -> 792.95154 | W39: =VLOOKUP($C39,$B$3:$X$358,MATCH(W$2,$B$2:$X$2,0),0)*$G39/VLOOKUP($C39,$B$3:$X$358,MATCH($G$2,$B$2:$X$2,0),0) -> 396.47577 | X39: =VLOOKUP($C39,$B$3:$X$358,MATCH(X$2,$B$2:$X$2,0),0)*$G39/VLOOKUP($C39,$B$3:$X$358,MATCH($G$2,$B$2:$X$2,0),0) -> 0 | AI39: =T39/G39 -> 0.017621145 | AM39: 0.019 | AN39: 0 | AO39: 0 | AP39: 0.4305 | AQ39: 0.11534667 | AS39: 0.72602959 | AT39: =$AT$228 -> 0.17824592 | AU39: 0.44001793 | AV39: 0.28601166 | AX39: =AI39*O39+P39*AM39 -> 0.018256229 | AY39: 14.05824 | AZ39: 0.7
A40: 407 | B40: Leek | D40: Vegetables | F40: 0.15 | G40: 0.129 | H40: 0.205 | I40: 212 | J40: 1634.2638 | K40: 1.891 | L40: 2.2668912 | M40: 2.0225619 | N40: 3.602424 | O40: 1 | P40: 0 | Q40: 0 | S40: =VLOOKUP($B40,Conversores_Dieta!$B$4:$J$164,Coefs!S$292,0) -> 0.65 | T40: =VLOOKUP($B40,Conversores_Dieta!$B$4:$J$164,Coefs!T$292,0) -> 0.0032 | U40: =VLOOKUP($B40,Conversores_Dieta!$B$4:$J$164,Coefs!U$292,0) -> 4 | V40: =VLOOKUP($B40,Conversores_Dieta!$B$4:$J$164,Coefs!V$292,0) -> 75 | W40: =VLOOKUP($B40,Conversores_Dieta!$B$4:$J$164,Coefs!W$292,0) -> 600 | X40: =VLOOKUP($B40,Conversores_Dieta!$B$4:$J$164,Coefs!X$292,0) -> 1230 | AI40: =T40/G40 -> 0.024806202 | AL40: 0.41 | AM40: 0.029 | AP40: 0.341 | AQ40: 0.11534667 | AS40: 0.72602959 | AT40: =$AT$228 -> 0.17824592 | AU40: 0.44001793 | AV40: 0.28601166 | AX40: =AI40*O40+P40*AM40 -> 0.024806202 | AY40: 17.5728 | AZ40: 0.7 | BA40: 28 | BB40: 0 | BC40: 0 | BD40: 2 | BE40: 1 | BF40: 9 | BG40: 2 | BH40: 110 | BI40: 7.27 | BJ40: 0 | BK40: 0 | BL40: 960 | BM40: 180 | BN40: 7.3 | BO40: 150 | BP40: 0.3
...

Sheet Sources
A1: Name_biomass | B1: BG_Biomass_kgDM_ha | C1: Root_Shoot_ratio | D1: Product_kgDM_kgFM | E1: Residue_kgDM_kgFM | F1: Conventional_kgDM_ha | G1: Organic_kgDM_ha | H1: GE_product_edible_portion_MJ_kgFM | I1: GE_product_residue_MJ_kgFM | J1: GE_product_MJ_kgFM | K1: GE_residue_MJ_kg | L1: kg_product_kg_aerial_biomass | M1: kg_residue_kg_aerial_biomass_FM | N1: kg_residue_kg_product_FM | O1: Product_kgN_kgDM | P1: Product_kgP_kgDM | Q1: Product_kgK_kgDM | R1: Product_kgC_kgDM | S1: Residue_kgN_kgDM | T1: Residue_kgP_kgDM | U1: Residue_kgK_kgDM | V1: Residue_kgC_kgDM | W1: Residue_humified_kgC_kgC | X1: MgDM_m3 | Y1: Root_kgC_kgDM | Z1: Root_humified_kgC_kgC | AA1: Root_mass_kgC_kgDM | AB1: Rhizodeposits_mass_kgC_kgDM | AC1: Residue_C_N | AD1: Root_kgN_kgDM | AE1: GE_Roots_MJ_kgDM | AF1: Rhizodeposits_N_kgN_kgRootN | AG1: Comments
A2: Oats | B2: Guzmán et al. 2014 | C2: Guzmán et al. (2014) | D2: Guzmán et al. 2014 | E2: Guzmán et al. 2014 | J2: Guzmán et al. 2014 | K2: Guzmán et al. 2014 | L2: Guzmán et al. 2014 | O2: FEDNA, 2016 | P2: FEDNA, 2016 | Q2: FEDNA, 2016 | R2: Wolf et al. (2015) | S2: IPCC (2019) | T2: FEDNA, 2016 ("Cereals") | U2: FEDNA, 2016 ("Cereals") | V2: =IF([1]C!G5="","",[1]C!G5) -> Carranca et al. (2009), ECN (2017) (2) | W2: =IF([1]Humus!G5="","",[1]Humus!G5) -> Cereals average | Y2: =IF([1]C!BF5="","",[1]C!BF5) -> Redin et al. (2014), Carranca et al. (2009) | Z2: =IF([1]Humus!AK5="","",[1]Humus!AK5) -> Herbaceous average | AA2: Based on root mass | AD2: IPCC (2006) Chapter 11. N2O from managed soils | AF2: Wang et al., 2020, Wichern et al., 2008, Fustec et al, 2010
A3: Barley | B3: Guzmán et al. 2014 | C3: Guzmán et al. (2014) | D3: Guzmán et al. 2014 | E3: Guzmán et al. 2014 | J3: Guzmán et al. 2014 | K3: Guzmán et al. 2014 | L3: Guzmán et al. 2014 | O3: FEDNA, 2016 | P3: FEDNA, 2016 | Q3: FEDNA, 2016 | R3: Wolf et al. (2015) | S3: IPCC (2019) | T3: FEDNA, 2016 ("Cereals") | U3: FEDNA, 2016 ("Cereals") | V3: =IF([1]C!G6="","",[1]C!G6) -> Nourbakhsh (2006), Parikh et al. (2007), Henriksen et al. (1999), ECN (2017) (10) | W3: =IF([1]Humus!G6="","",[1]Humus!G6) -> Cereals average | Y3: =IF([1]C!BF6="","",[1]C!BF6) -> Redin et al. (2014) | Z3: =IF([1]Humus!AK6="","",[1]Humus!AK6) -> Herbaceous average | AA3: Based on root mass | AD3: IPCC (2006) Chapter 11. N2O from managed soils | AF3: Wang et al., 2020, Wichern et al., 2008, Fustec et al, 2010
A4: Rice | C4: Wolf et al. (2015) | D4: Guzmán et al. 2014 | E4: Guzmán et al. 2014 | J4: Guzmán et al. 2014 | K4: Guzmán et al. 2014 | L4: Guzmán et al. 2014 | O4: FEDNA, 2016 | P4: FEDNA, 2016 | Q4: FEDNA, 2016 | R4: Wolf et al. (2015) | S4: IPCC (2019) | T4: FEDNA, 2016 ("Cereals") | U4: FEDNA, 2016 ("Cereals") | V4: =IF([1]C!G7="","",[1]C!G7) -> Parikh et al. (2007), Wang et al.(2017), Chen et al (2015), Lou et al (2007), Su et al (2016), Levi-Minzi et al. (1990), ECN (2017) (8) | W4: =IF([1]Humus!G7="","",[1]Humus!G7) -> Cereals average | Y4: =IF([1]C!BF7="","",[1]C!BF7) -> Lou et al. (2007) | Z4: =IF([1]Humus!AK7="","",[1]Humus!AK7) -> Herbaceous average | AA4: Based on root mass | AD4: IPCC (2006) Chapter 11. N2O from managed soils | AF4: Wang et al., 2020, Wichern et al., 2008, Fustec et al, 2010
A5: Millet | C5: Wolf et al. (2015) | D5: Guzmán et al. 2014 | E5: Guzmán et al. 2014 | J5: Guzmán et al. 2014 | K5: Guzmán et al. 2014 | L5: Guzmán et al. 2014 | O5: FEDNA, 2016 | P5: FEDNA, 2016 | Q5: FEDNA, 2016 | R5: Wolf et al. (2015) | S5: IPCC (2019) | T5: FEDNA, 2016 ("Cereals") | U5: FEDNA, 2016 ("Cereals") | V5: =IF([1]C!G8="","",[1]C!G8) -> Summer cereals | W5: =IF([1]Humus!G8="","",[1]Humus!G8) -> Cereals average | Y5: =IF([1]C!BF8="","",[1]C!BF8) -> Redin et al. (2014) | Z5: =IF([1]Humus!AK8="","",[1]Humus!AK8) -> Herbaceous average | AA5: Based on root mass | AD5: IPCC (2006) Chapter 11. N2O from managed soils | AF5: Wang et al., 2020, Wichern et al., 2008, Fustec et al, 2010
A6: Rye | C6: Wolf et al. (2015) | D6: Guzmán et al. 2014 | E6: Guzmán et al. 2014 | J6: Guzmán et al. 2014 | K6: Guzmán et al. 2014 | L6: Guzmán et al. 2014 | O6: FEDNA, 2016 | P6: FEDNA, 2016 | Q6: FEDNA, 2016 | R6: Wolf et al. (2015) | S6: IPCC (2019) | T6: FEDNA, 2016 ("Cereals") | U6: FEDNA, 2016 ("Cereals") | V6: =IF([1]C!G9="","",[1]C!G9) -> Parikh et al. (2007), ECN (2017) (4) | W6: =IF([1]Humus!G9="","",[1]Humus!G9) -> Cereals average | Y6: =IF([1]C!BF9="","",[1]C!BF9) -> Redin et al. (2014) | Z6: =IF([1]Humus!AK9="","",[1]Humus!AK9) -> Herbaceous average | AA6: Based on root mass | AD6: IPCC (2006) Chapter 11. N2O from managed soils | AF6: Wang et al., 2020, Wichern et al., 2008, Fustec et al, 2010
A7: Sorghum | C7: Guzmán et al. (2014) | D7: Guzmán et al. 2014 | E7: Guzmán et al. 2014 | J7: Guzmán et al. 2014 | K7: Guzmán et al. 2014 | L7: Guzmán et al. 2014 | O7: Lassaletta et al., 2014 (from FAO, 2011) | P7: Summer cereals | Q7: Summer cereals | R7: Wolf et al. (2015) | S7: IPCC (2019) | T7: FEDNA, 2016 ("Cereals") | U7: FEDNA, 2016 ("Cereals") | V7: =IF([1]C!G10="","",[1]C!G10) -> ECN (2017) (10) | W7: =IF([1]Humus!G10="","",[1]Humus!G10) -> Cereals average | Y7: =IF([1]C!BF10="","",[1]C!BF10) -> Redin et al. (2014) | Z7: =IF([1]Humus!AK10="","",[1]Humus!AK10) -> Herbaceous average | AA7: Based on root mass | AD7: IPCC (2006) Chapter 11. N2O from managed soils | AF7: Wang et al., 2020, Wichern et al., 2008, Fustec et al, 2010
A8: Wheat | B8: Guzmán et al. 2014 | C8: Guzmán et al. (2014) | D8: Guzmán et al. 2014 | E8: Guzmán et al. 2014 | J8: Guzmán et al. 2014 | K8: Guzmán et al. 2014 | L8: Guzmán et al. 2014 | O8: FEDNA, 2016 | P8: FEDNA, 2016 | Q8: FEDNA, 2016 | R8: Wolf et al. (2015) | S8: IPCC (2019) | T8: FEDNA, 2016 ("Cereals") | U8: FEDNA, 2016 ("Cereals") | V8: =IF([1]C!G11="","",[1]C!G11) -> Rahn and Lillywhite (2002), Boiffin et al. (1986), Mondini et al. (2017), Nourbakhsh (2006), Parikh et al. (2007), Hadas et al. (2004), Huang et al. (2004), Raiesi (2006), Wang et al.(2017), Bremer et al. (1991), Triberti et al. (2008), Cayuela et al. (2009), Aita et aL (2012), Havstad et al (2009), Chen et al (2015), Gan et al. (2009) (2), Henriksen et al. (1999), ECN (2017) (21), Sarrantonio (2003) | W8: =IF([1]Humus!G11="","",[1]Humus!G11) -> Delas and Molot (1983), Thomsen and Christensen (2004) | Y8: =IF([1]C!BF11="","",[1]C!BF11) -> Redin et al. (2014) | Z8: =IF([1]Humus!AK11="","",[1]Humus!AK11) -> Herbaceous average | AA8: Based on root mass | AD8: IPCC (2006) Chapter 11. N2O from managed soils | AF8: Wang et al., 2020, Wichern et al., 2008, Fustec et al, 2010
A9: Maize | B9: Guzmán et al. 2014 | C9: Guzmán et al. (2014) | D9: Guzmán et al. 2014 | E9: Guzmán et al. 2014 | J9: Guzmán et al. 2014 | K9: Guzmán et al. 2014 | L9: Guzmán et al. 2014 | O9: FEDNA, 2016 | P9: FEDNA, 2016 | Q9: FEDNA, 2016 | R9: Wolf et al. (2015) | S9: IPCC (2019) | T9: FEDNA, 2016 ("Cereals") | U9: FEDNA, 2016 ("Cereals") | V9: =IF([1]C!G12="","",[1]C!G12) -> Boiffin et al. (1986), Nourbakhsh (2006), Paula et al. (2011), Abro et al. (2011), Hadas et al. (2004), Li et al. (2013), Potthoff et al. (2005), Wang et al.(2017), Triberti et al. (2008), Chen et al (2015), Johnson et al (2007), Delas and Molot (1983), ECN (2017) (6) | W9: =IF([1]Humus!G12="","",[1]Humus!G12) -> Boiffin et al. (1986), Barber 1979, Plenet et al. 1993, Delas and Molot (1983), Thomsen and Christensen (2010) | Y9: =IF([1]C!BF12="","",[1]C!BF12) -> Redin et al. (2014), Johnson et al. (2007) | Z9: =IF([1]Humus!AK12="","",[1]Humus!AK12) -> Bolinder et al. (1999), Barber (1979) (2), Plenet et al. (1993) (2) | AA9: Based on root mass | AD9: IPCC (2006) Chapter 11. N2O from managed soils | AF9: Wang et al., 2020, Wichern et al., 2008, Fustec et al, 2010
A10: Winter cereals, other | C10: Oats, barley, wheat, rye | D10: Guzmán et al. 2014 | E10: Guzmán et al. 2014 | J10: Guzmán et al. 2014 | K10: Guzmán et al. 2014 | L10: Guzmán et al. 2014 | O10: Oats, barley, wheat | P10: Oats, barley, wheat | Q10: Oats, barley, wheat | R10: Oats, barley, wheat, rye | S10: "Cereals" (de Blas et al. 2019) | T10: Oats, barley, wheat | U10: Oats, barley, wheat | V10: =IF([1]C!G13="","",[1]C!G13) -> Average of available data | W10: =IF([1]Humus!G13="","",[1]Humus!G13) -> Katterer et al. (2011), Andren and Katterer (1997), Boiffin et al. (1986) | Y10: =IF([1]C!BF13="","",[1]C!BF13) -> Average of available data | Z10: =IF([1]Humus!AK13="","",[1]Humus!AK13) -> Herbaceous average | AA10: Based on root mass | AD10: IPCC (2006) Chapter 11. N2O from managed soils | AF10: Wang et al., 2020, Wichern et al., 2008, Fustec et al, 2010
A11: Summer cereals, other | C11: Sorghum, maize, millet, rice | D11: Sorghum, maize | E11: Sorghum, maize | J11: Sorghum, maize | K11: Sorghum, maize | L11: Guzmán et al. 2014 | O11: Sorghum, maize | P11: Sorghum, maize | Q11: Sorghum, maize | R11: Sorghum, maize, millet, rice | S11: "Cereals" (de Blas et al. 2019) | T11: Sorghum, maize | U11: Sorghum, maize | V11: =IF([1]C!G14="","",[1]C!G14) -> Average of available data | W11: =IF([1]Humus!G14="","",[1]Humus!G14) -> Cereals average | Y11: =IF([1]C!BF14="","",[1]C!BF14) -> Average of available data | Z11: =IF([1]Humus!AK14="","",[1]Humus!AK14) -> Herbaceous average | AA11: Based on root mass | AD11: IPCC (2006) Chapter 11. N2O from managed soils | AF11: Wang et al., 2020, Wichern et al., 2008, Fustec et al, 2010
A12: Triticale | C12: Winter cereals, other | D12: Winter cereals, other | E12: Winter cereals, other | F12: Winter cereals, other | G12: Winter cereals, other | H12: Winter cereals, other | I12: Winter cereals, other | J12: Winter cereals, other | K12: Winter cereals, other | L12: Winter cereals, other | M12: Winter cereals, other | N12: Winter cereals, other | O12: Winter cereals, other | P12: Winter cereals, other | Q12: Winter cereals, other | R12: Winter cereals, other | S12: "Cereals" (de Blas et al. 2019) | T12: Winter cereals, other | U12: Winter cereals, other | V12: Winter cereals, other | W12: Winter cereals, other | X12: Winter cereals, other | Y12: =IF([1]C!BF15="","",[1]C!BF15) | Z12: =IF([1]Humus!AK15="","",[1]Humus!AK15) | AA12: Based on root mass | AC12: Winter cereals, other | AD12: Winter cereals, other | AF12: Wang et al., 2020, Wichern et al., 2008, Fustec et al, 2010
A13: Canary grass | C13: Winter cereals, other | D13: Winter cereals, other | E13: Winter cereals, other | F13: Winter cereals, other | G13: Winter cereals, other | H13: Winter cereals, other | I13: Winter cereals, other | J13: Winter cereals, other | K13: Winter cereals, other | L13: Winter cereals, other | M13: Winter cereals, other | N13: Winter cereals, other | O13: Winter cereals, other | P13: Winter cereals, other | Q13: Winter cereals, other | R13: Winter cereals, other | S13: "Cereals" (de Blas et al. 2019) | T13: Winter cereals, other | U13: Winter cereals, other | V13: Winter cereals, other | W13: Winter cereals, other | X13: Winter cereals, other | Y13: =IF([1]C!BF16="","",[1]C!BF16) -> Modern varieties | Z13: =IF([1]Humus!AK16="","",[1]Humus!AK16) -> Herbaceous average | AA13: Based on root mass | AC13: Winter cereals, other | AD13: Winter cereals, other | AF13: Wang et al., 2020, Wichern et al., 2008, Fustec et al, 2010
A14: Cereals nes | C14: Winter cereals, other | D14: Winter cereals, other | E14: Winter cereals, other | F14: Winter cereals, other | G14: Winter cereals, other | H14: Winter cereals, other | I14: Winter cereals, other | J14: Winter cereals, other | K14: Winter cereals, other | L14: Winter cereals, other | M14: Winter cereals, other | N14: Winter cereals, other | O14: Winter cereals, other | P14: Winter cereals, other | Q14: Winter cereals, other | R14: Winter cereals, other | S14: "Cereals" (de Blas et al. 2019) | T14: Winter cereals, other | U14: Winter cereals, other | V14: Winter cereals, other | W14: Winter cereals, other | X14: Winter cereals, other | Y14: =IF([1]C!BF17="","",[1]C!BF17) -> Modern varieties | Z14: =IF([1]Humus!AK17="","",[1]Humus!AK17) -> Herbaceous average | AA14: Based on root mass | AC14: Winter cereals, other | AD14: Winter cereals, other | AF14: Wang et al., 2020, Wichern et al., 2008, Fustec et al, 2010
