Workbook
Name fish: #REF!
Name fish: [1]HS6_list!$E$6:$L$288
Name fish: [1]HS6_list!$E$6:$L$288
Name fish: [1]HS6_list!$E$6:$L$288
Name fish: [1]HS6_list!$E$6:$L$288
Name fish: [1]HS6_list!$E$6:$L$288
Name fish: [1]HS6_list!$E$6:$L$288
Name fish: [1]HS6_list!$E$6:$L$288
Name fish: [1]HS6_list!$E$6:$L$288
Name fish: [1]HS6_list!$E$6:$L$288
Name fish: [1]HS6_list!$E$6:$L$288
Name fish: [1]HS6_list!$E$6:$L$288
Name fish: [1]HS6_list!$E$6:$L$288
Name fish: [1]HS6_list!$E$6:$L$288
Name fish: #REF!
Name fish: [1]HS6_list!$E$6:$L$288
Name fish: [1]HS6_list!$E$6:$L$288
Name fish: [1]HS6_list!$E$6:$L$288
Name fish: #REF!
Name fish: [1]HS6_list!$E$6:$L$288
Name fish: [1]HS6_list!$E$6:$L$288
Name fish: [1]HS6_list!$E$6:$L$288
Name fish: [1]HS6_list!$E$6:$L$288
Name fish: #REF!
Name fish_map: #REF!
Name fish_map: #REF!
Name fish_map: #REF!
Name fish_map: #REF!
Name fish_map: #REF!
Name fish_map: #REF!
Name fish_map: #REF!
Name fish_map: #REF!
Name fish_map: #REF!
Name fish_map: #REF!
Name fish_map: #REF!
Name fish_map: #REF!
Name fish_map: #REF!
Name fish_map: #REF!
Name fish_map: #REF!
Name fish_map: #REF!
Name fish_map: #REF!
Name fish_map: #REF!
Name fish_map: #REF!
Name fish_map: #REF!
Name fish_map: #REF!
Name fish_map: #REF!
Name fish_map: #REF!
Name fish_map: #REF!
Name hs4list: #REF!
Name hs4list: #REF!
Name hs4list: #REF!
Name hs4list: #REF!
Name hs4list: #REF!
Name hs4list: #REF!
Name hs4list: #REF!
Name hs4list: #REF!
Name hs4list: #REF!
Name hs4list: #REF!
Name hs4list: #REF!
Name hs4list: #REF!

Sheet FAO_areas
A1: Area.Code | B1: Area.Code..M49. | C1: Area | D1: 1961 | E1: 1962 | F1: 1963 | G1: 1964 | H1: 1965 | I1: 1966 | J1: 1967 | K1: 1968 | L1: 1969 | M1: 1970 | N1: 1971 | O1: 1972 | P1: 1973 | Q1: 1974 | R1: 1975 | S1: 1976 | T1: 1977 | U1: 1978 | V1: 1979 | W1: 1980 | X1: 1981 | Y1: 1982 | Z1: 1983 | AA1: 1984 | AB1: 1985 | AC1: 1986 | AD1: 1987 | AE1: 1988 | AF1: 1989 | AG1: 1990 | AH1: 1991 | AI1: 1992 | AJ1: 1993 | AK1: 1994 | AL1: 1995 | AM1: 1996 | AN1: 1997 | AO1: 1998 | AP1: 1999 | AQ1: 2000 | AR1: 2001 | AS1: 2002 | AT1: 2003 | AU1: 2004 | AV1: 2005 | AW1: 2006 | AX1: 2007 | AY1: 2008 | AZ1: 2009 | BA1: 2010 | BB1: 2011 | BC1: 2012 | BD1: 2013 | BE1: 2014 | BF1: 2015 | BG1: 2016 | BH1: 2017 | BI1: 2018 | BJ1: 2019 | BK1: 2020 | BL1: 2021
A2: 1 | B2: '051 | C2: Armenia | AI2: 0.558804 | AJ2: 0.582316 | AK2: 0.549204 | AL2: 0.497124 | AM2: 0.559657 | AN2: 0.573034 | AO2: 0.549734 | AP2: 0.514569 | AQ2: 0.502544 | AR2: 0.570666 | AS2: 0.551215 | AT2: 0.57892 | AU2: 0.610678 | AV2: 0.619221 | AW2: 0.535203 | AX2: 0.572803 | AY2: 0.568765 | AZ2: 0.550857 | BA2: 0.526334 | BB2: 0.536896 | BC2: 0.57482 | BD2: 0.591657 | BE2: 0.602185 | BF2: 0.634306 | BG2: 0.649743 | BH2: 0.551269 | BI2: 0.476292 | BJ2: 0.442291 | BK2: 0.451925 | BL2: 0.357216
A3: 2 | B3: '004 | C3: Afghanistan | D3: 7.245424 | E3: 7.484716 | F3: 7.520068 | G3: 7.579998 | H3: 7.562049 | I3: 7.55436 | J3: 6.90767 | K3: 6.74611 | L3: 6.83225 | M3: 7.02577 | N3: 7.46557 | O3: 8.52386 | P3: 7.39652 | Q3: 7.47267 | R3: 7.57758 | S3: 7.66948 | T3: 7.57558 | U3: 7.565937 | V3: 7.11096 | W3: 6.73806 | X3: 6.5449 | Y3: 6.29743 | Z3: 5.97986 | AA3: 5.792265 | AB3: 5.541895 | AC3: 5.314235 | AD3: 5.56217 | AE3: 5.23216 | AF3: 5.14819 | AG3: 5.048558 | AH3: 5.701755 | AI3: 5.491887 | AJ3: 6.28148 | AK3: 6.52541 | AL3: 6.355857 | AM3: 6.433566 | AN3: 6.480347 | AO3: 6.604257 | AP3: 6.070088 | AQ3: 5.762227 | AR3: 5.13106 | AS3: 5.412389 | AT3: 6.904977 | AU3: 6.178623 | AV3: 7.066848 | AW3: 6.939692 | AX3: 7.022634 | AY3: 6.412082 | AZ3: 7.39669 | BA3: 6.965182 | BB3: 6.560078 | BC3: 7.21623 | BD3: 7.27253 | BE3: 7.727187 | BF3: 6.708478 | BG3: 7.135674 | BH3: 6.125424 | BI3: 5.068016 | BJ3: 6.978333 | BK3: 7.926427 | BL3: 6.140869
A4: 3 | B4: '008 | C4: Albania | D4: 0.855417 | E4: 0.838959 | F4: 0.799436 | G4: 0.887689 | H4: 0.838712 | I4: 0.870198 | J4: 0.896933 | K4: 0.897334 | L4: 0.902807 | M4: 0.910566 | N4: 0.87243 | O4: 0.91204 | P4: 0.924 | Q4: 0.92758 | R4: 0.9109 | S4: 0.9816 | T4: 1.0028 | U4: 1.0065 | V4: 1.0326 | W4: 1.060632 | X4: 1.0397 | Y4: 1.0258 | Z4: 1.0094 | AA4: 0.9852 | AB4: 1.048642 | AC4: 1.06536 | AD4: 1.066896 | AE4: 1.070416 | AF4: 1.058282 | AG4: 0.962206 | AH4: 0.747181 | AI4: 0.711872 | AJ4: 0.782764 | AK4: 0.799353 | AL4: 0.725224 | AM4: 0.692033 | AN4: 0.703379 | AO4: 0.703779 | AP4: 0.635785 | AQ4: 0.616692 | AR4: 0.574746 | AS4: 0.557434 | AT4: 0.567357 | AU4: 0.554407 | AV4: 0.548375 | AW4: 0.546009 | AX4: 0.508766 | AY4: 0.583125 | AZ4: 0.56841 | BA4: 0.561594 | BB4: 0.563576 | BC4: 0.575448 | BD4: 0.572627 | BE4: 0.578253 | BF4: 0.583647 | BG4: 0.587332 | BH4: 0.595585 | BI4: 0.586876 | BJ4: 0.579187 | BK4: 0.580976 | BL4: 0.58982
A5: 4 | B5: '012 | C5: Algeria | D5: 6.817646 | E5: 7.29632 | F5: 7.272325 | G5: 7.08443 | H5: 7.151738 | I5: 5.19543 | J5: 6.57049 | K5: 7.46836 | L5: 7.54359 | M5: 7.97881 | N5: 7.48641 | O5: 8.62213 | P5: 8.05467 | Q5: 7.59043 | R5: 8.05559 | S5: 8.41508 | T5: 7.23079 | U5: 6.92949 | V5: 7.52438 | W5: 8.11731 | X5: 7.45699 | Y5: 6.75551 | Z5: 6.157736 | AA5: 7.098574 | AB5: 8.33285 | AC5: 7.62527 | AD5: 7.36949 | AE5: 5.41994 | AF5: 7.06504 | AG5: 6.454954 | AH5: 8.895348 | AI5: 9.064257 | AJ5: 5.887485 | AK5: 4.509832 | AL5: 7.087178 | AM5: 9.228186 | AN5: 4.218588 | AO5: 8.98894 | AP5: 5.641989 | AQ5: 3.902215 | AR5: 6.625521 | AS5: 5.617244 | AT5: 7.902951 | AU5: 8.227278 | AV5: 7.066841 | AW5: 7.838878 | AX5: 8.251669 | AY5: 5.505953 | AZ5: 8.96647 | BA5: 8.612711 | BB5: 8.168953 | BC5: 9.178356 | BD5: 8.572979 | BE5: 8.11385 | BF5: 8.533148 | BG5: 10.045954 | BH5: 10.359991 | BI5: 9.458586 | BJ5: 9.67256 | BK5: 9.063437 | BL5: 7.081964
A6: 7 | B6: '024 | C6: Angola | D6: 2.990275 | E6: 3.248897 | F6: 3.246638 | G6: 3.257 | H6: 3.221724 | I6: 3.293657 | J6: 3.347989 | K6: 3.396567 | L6: 3.559023 | M6: 3.396175 | N6: 3.453475 | O6: 3.44857 | P6: 3.55817 | Q6: 3.50267 | R6: 3.2477 | S6: 3.0659 | T6: 3.0366 | U6: 3.017 | V6: 2.9685 | W6: 2.895 | X6: 2.8401 | Y6: 2.8831 | Z6: 2.9159 | AA6: 2.9613 | AB6: 3.0065 | AC6: 3.4149 | AD6: 3.5279 | AE6: 3.5348 | AF6: 3.4832 | AG6: 3.007091 | AH6: 3.574067 | AI6: 3.880173 | AJ6: 4.205419 | AK6: 3.982899 | AL6: 3.608599 | AM6: 3.586183 | AN6: 3.626611 | AO6: 3.973026 | AP6: 3.797744 | AQ6: 4.0524 | AR6: 4.585654 | AS6: 5.000968 | AT6: 5.513234 | AU6: 6.594528 | AV6: 6.945744 | AW6: 6.908741 | AX6: 7.661619 | AY6: 6.304829 | AZ6: 9.007867 | BA6: 9.209633 | BB6: 10.425454 | BC6: 7.302954 | BD6: 10.696133 | BE6: 9.95105 | BF6: 10.028192 | BG6: 12.256618 | BH6: 12.575325 | BI6: 12.340178 | BJ6: 12.156901 | BK6: 12.405009 | BL6: 12.464356
A7: 8 | B7: '028 | C7: Antigua and Barbuda | D7: 0.011012 | E7: 0.010411 | F7: 0.010855 | G7: 0.009388 | H7: 0.007386 | I7: 0.003526 | J7: 0.003569 | K7: 0.001355 | L7: 0.002818 | M7: 0.003194 | N7: 0.008464 | O7: 0.001408 | P7: 0.001148 | Q7: 0.000764 | R7: 0.000773 | S7: 0.000951 | T7: 0.000716 | U7: 0.000869 | V7: 0.00114 | W7: 0.001063 | X7: 0.001136 | Y7: 0.001087 | Z7: 0.000886 | AA7: 0.000714 | AB7: 0.00421 | AC7: 0.004152 | AD7: 0.004264 | AE7: 0.004382 | AF7: 0.004068 | AG7: 0.003847 | AH7: 0.006108 | AI7: 0.006228 | AJ7: 0.006183 | AK7: 0.006176 | AL7: 0.005604 | AM7: 0.005698 | AN7: 0.005775 | AO7: 0.005748 | AP7: 0.005832 | AQ7: 0.00603 | AR7: 0.006001 | AS7: 0.006364 | AT7: 0.006692 | AU7: 0.006837 | AV7: 0.006014 | AW7: 0.006238 | AX7: 0.00647 | AY7: 0.006619 | AZ7: 0.006715 | BA7: 0.00687 | BB7: 0.006915 | BC7: 0.006602 | BD7: 0.006593 | BE7: 0.006572 | BF7: 0.006638 | BG7: 0.006478 | BH7: 0.006237 | BI7: 0.006079 | BJ7: 0.005973 | BK7: 0.005733 | BL7: 0.006094
A8: 9 | B8: '032 | C8: Argentina | D8: 25.314554 | E8: 22.530842 | F8: 27.849174 | G8: 29.496232 | H8: 25.002891 | I8: 27.18808 | J8: 29.171299 | K8: 29.242528 | L8: 28.727747 | M8: 27.50735 | N8: 29.788684 | O8: 28.170517 | P8: 28.422198 | Q8: 28.274081 | R8: 28.848048 | S8: 31.610761 | T8: 27.27266 | U8: 30.69887 | V8: 30.082827 | W8: 29.029615 | X8: 32.424637 | Y8: 36.48896 | Z8: 35.964428 | AA8: 34.243211 | AB8: 33.105144 | AC8: 31.093689 | AD8: 28.910946 | AE8: 28.583308 | AF8: 27.27883 | AG8: 28.890194 | AH8: 47.615078 | AI8: 47.129822 | AJ8: 43.510446 | AK8: 46.743649 | AL8: 51.61278 | AM8: 53.61204 | AN8: 60.59014 | AO8: 60.447507 | AP8: 63.086211 | AQ8: 63.6956 | AR8: 64.222114 | AS8: 66.367944 | AT8: 68.11449 | AU8: 71.779567 | AV8: 73.944018 | AW8: 74.599204 | AX8: 80.537725 | AY8: 84.306284 | AZ8: 77.776228 | BA8: 81.425679 | BB8: 90.850569 | BC8: 88.499057 | BD8: 90.736303 | BE8: 90.088102 | BF8: 93.516935 | BG8: 93.038929 | BH8: 92.125701 | BI8: 91.11152 | BJ8: 92.762084 | BK8: 95.159328 | BL8: 95.42235
A9: 10 | B9: '036 | C9: Australia | D9: 17.820915 | E9: 19.264129 | F9: 19.399336 | G9: 20.708313 | H9: 20.748558 | I9: 24.158353 | J9: 24.927578 | K9: 29.436834 | L9: 26.78675 | M9: 22.497741 | N9: 24.863225 | O9: 24.807914 | P9: 27.357289 | Q9: 25.173011 | R9: 26.912875 | S9: 27.596543 | T9: 30.893882 | U9: 31.801524 | V9: 32.811856 | W9: 33.083711 | X9: 35.918398 | Y9: 34.60363 | Z9: 40.368844 | AA9: 38.861055 | AB9: 38.025647 | AC9: 35.847808 | AD9: 32.652757 | AE9: 31.653625 | AF9: 31.110856 | AG9: 31.36389 | AH9: 33.679176 | AI9: 30.889746 | AJ9: 33.196307 | AK9: 35.451338 | AL9: 32.956236 | AM9: 37.868377 | AN9: 42.84067 | AO9: 42.502697 | AP9: 46.63086 | AQ9: 48.149855 | AR9: 48.174382 | AS9: 46.858093 | AT9: 44.610551 | AU9: 50.088676 | AV9: 51.343444 | AW9: 48.462413 | AX9: 45.351812 | AY9: 49.421841 | AZ9: 52.638987 | BA9: 52.678411 | BB9: 52.201912 | BC9: 54.109123 | BD9: 53.336633 | BE9: 50.705 | BF9: 51.387955 | BG9: 48.634577 | BH9: 55.27951 | BI9: 52.442054 | BJ9: 46.420916 | BK9: 43.933647 | BL9: 55.798345
A10: 11 | B10: '040 | C10: Austria | D10: 2.350618 | E10: 2.354237 | F10: 2.338705 | G10: 2.355749 | H10: 2.257076 | I10: 2.332565 | J10: 2.323879 | K10: 2.336605 | L10: 2.389996 | M10: 2.384104 | N10: 2.384159 | O10: 2.40613 | P10: 2.387477 | Q10: 2.400034 | R10: 2.37835 | S10: 2.448059 | T10: 2.436637 | U10: 2.469401 | V10: 2.509165 | W10: 2.530671 | X10: 2.50944 | Y10: 2.504649 | Z10: 2.479836 | AA10: 2.469487 | AB10: 2.554286 | AC10: 2.53766 | AD10: 2.495912 | AE10: 2.44466 | AF10: 2.431202 | AG10: 2.441981 | AH10: 2.567892 | AI10: 2.563349 | AJ10: 2.551296 | AK10: 2.552986 | AL10: 2.417596 | AM10: 2.39999 | AN10: 2.44915 | AO10: 2.452417 | AP10: 2.415751 | AQ10: 2.371423 | AR10: 2.374817 | AS10: 2.350729 | AT10: 2.320124 | AU10: 2.312124 | AV10: 2.302865 | AW10: 2.305269 | AX10: 2.34031 | AY10: 2.394139 | AZ10: 2.40636 | BA10: 2.396224 | BB10: 2.378773 | BC10: 2.368593 | BD10: 2.31416 | BE10: 2.372821 | BF10: 2.328966 | BG10: 2.347122 | BH10: 2.342042 | BI10: 2.0159 | BJ10: 1.99837 | BK10: 1.98175 | BL10: 1.97486
A11: 12 | B11: '044 | C11: Bahamas | D11: 0.005286 | E11: 0.005534 | F11: 0.005786 | G11: 0.006054 | H11: 0.006286 | I11: 0.007384 | J11: 0.008154 | K11: 0.008094 | L11: 0.007684 | M11: 0.008708 | N11: 0.00746 | O11: 0.010048 | P11: 0.01005 | Q11: 0.010342 | R11: 0.011206 | S11: 0.011758 | T11: 0.011628 | U11: 0.01111 | V11: 0.011262 | W11: 0.011128 | X11: 0.011724 | Y11: 0.01163 | Z11: 0.011228 | AA11: 0.011706 | AB11: 0.0137 | AC11: 0.013306 | AD11: 0.013152 | AE11: 0.013611 | AF11: 0.013932 | AG11: 0.013986 | AH11: 0.013332 | AI11: 0.012395 | AJ11: 0.012128 | AK11: 0.012005 | AL11: 0.01237 | AM11: 0.012362 | AN11: 0.012806 | AO11: 0.012566 | AP11: 0.013104 | AQ11: 0.014546 | AR11: 0.01547 | AS11: 0.014122 | AT11: 0.014236 | AU11: 0.01474 | AV11: 0.014632 | AW11: 0.0156 | AX11: 0.015687 | AY11: 0.015546 | AZ11: 0.015073 | BA11: 0.017741 | BB11: 0.018053 | BC11: 0.018796 | BD11: 0.018312 | BE11: 0.019344 | BF11: 0.019608 | BG11: 0.019624 | BH11: 0.019793 | BI11: 0.020002 | BJ11: 0.020126 | BK11: 0.02035 | BL11: 0.020524
A12: 13 | B12: '048 | C12: Bahrain | D12: 0.004376 | E12: 0.004486 | F12: 0.004536 | G12: 0.004536 | H12: 0.004555 | I12: 0.00423 | J12: 0.004253 | K12: 0.004262 | L12: 0.004294 | M12: 0.004345 | N12: 0.004377 | O12: 0.004438 | P12: 0.004503 | Q12: 0.004765 | R12: 0.006248 | S12: 0.007928 | T12: 0.009791 | U12: 0.010058 | V12: 0.010151 | W12: 0.010251 | X12: 0.005676 | Y12: 0.004513 | Z12: 0.004644 | AA12: 0.004674 | AB12: 0.005477 | AC12: 0.005803 | AD12: 0.006338 | AE12: 0.006383 | AF12: 0.006434 | AG12: 0.00511 | AH12: 0.004981 | AI12: 0.00512 | AJ12: 0.005325 | AK12: 0.005376 | AL12: 0.005413 | AM12: 0.005404 | AN12: 0.00535 | AO12: 0.005559 | AP12: 0.005119 | AQ12: 0.005163 | AR12: 0.004858 | AS12: 0.006427 | AT12: 0.006496 | AU12: 0.006294 | AV12: 0.005936 | AW12: 0.007392 | AX12: 0.007305 | AY12: 0.006075 | AZ12: 0.006172 | BA12: 0.006473 | BB12: 0.007597 | BC12: 0.008374 | BD12: 0.009097 | BE12: 0.009939 | BF12: 0.009473 | BG12: 0.009912 | BH12: 0.007725 | BI12: 0.007719 | BJ12: 0.007817 | BK12: 0.007877 | BL12: 0.007898
A13: 14 | B13: '052 | C13: Barbados | D13: 0.046812 | E13: 0.046626 | F13: 0.04441 | G13: 0.047956 | H13: 0.048092 | I13: 0.048016 | J13: 0.049036 | K13: 0.04893 | L13: 0.04762 | M13: 0.047762 | N13: 0.047284 | O13: 0.043676 | P13: 0.044228 | Q13: 0.039412 | R13: 0.038832 | S13: 0.037886 | T13: 0.038396 | U13: 0.039402 | V13: 0.039478 | W13: 0.04141 | X13: 0.040284 | Y13: 0.040642 | Z13: 0.03784 | AA13: 0.035468 | AB13: 0.035022 | AC13: 0.035108 | AD13: 0.033624 | AE13: 0.030536 | AF13: 0.030056 | AG13: 0.028933 | AH13: 0.028683 | AI13: 0.026171 | AJ13: 0.02365 | AK13: 0.027764 | AL13: 0.026324 | AM13: 0.027125 | AN13: 0.025473 | AO13: 0.02409 | AP13: 0.022587 | AQ13: 0.023358 | AR13: 0.022483 | AS13: 0.021577 | AT13: 0.021256 | AU13: 0.019739 | AV13: 0.020207 | AW13: 0.019673 | AX13: 0.018968 | AY13: 0.019714 | AZ13: 0.01956 | BA13: 0.016731 | BB13: 0.016519 | BC13: 0.015629 | BD13: 0.01441 | BE13: 0.013505 | BF13: 0.011994 | BG13: 0.009106 | BH13: 0.011208 | BI13: 0.012278 | BJ13: 0.012369 | BK13: 0.010585 | BL13: 0.009257
A14: 15 | B14: '058 | C14: Belgium-Luxembourg | D14: 1.486415 | E14: 1.475185 | F14: 1.420987 | G14: 1.42972 | H14: 1.419874 | I14: 1.500726 | J14: 1.471975 | K14: 1.468307 | L14: 1.451695 | M14: 1.414483 | N14: 1.408026 | O14: 1.416715 | P14: 1.409668 | Q14: 1.371242 | R14: 1.327795 | S14: 1.314685 | T14: 1.297222 | U14: 1.313405 | V14: 1.299947 | W14: 1.27622 | X14: 1.256606 | Y14: 1.257011 | Z14: 1.221793 | AA14: 1.244917 | AB14: 1.231231 | AC14: 1.224669 | AD14: 1.211898 | AE14: 1.232069 | AF14: 1.229596 | AG14: 1.203634 | AH14: 1.215914 | AI14: 1.210653 | AJ14: 1.191284 | AK14: 1.162744 | AL14: 1.170923 | AM14: 1.164 | AN14: 1.16292 | AO14: 1.238409 | AP14: 1.191652
A15: 16 | B15: '050 | C15: Bangladesh | D15: 20.466749 | E15: 20.812562 | F15: 21.461093 | G15: 21.872808 | H15: 22.341619 | I15: 21.827772 | J15: 23.720076 | K15: 23.41834 | L15: 24.883088 | M15: 24.021363 | N15: 22.59994 | O15: 23.479265 | P15: 24.07651 | Q15: 23.796421 | R15: 25.037441 | S15: 24.549012 | T15: 25.132695 | U15: 25.411867 | V15: 25.668426 | W15: 26.21336 | X15: 26.802315 | Y15: 26.811727 | Z15: 25.284245 | AA15: 26.300693 | AB15: 27.205696 | AC15: 27.360935 | AD15: 26.47954 | AE15: 26.10302 | AF15: 26.592873 | AG15: 26.624419 | AH15: 28.088376 | AI15: 27.900845 | AJ15: 27.219028 | AK15: 27.426707 | AL15: 27.408014 | AM15: 28.046439 | AN15: 28.308796 | AO15: 27.900599 | AP15: 29.211178 | AQ15: 28.892006 | AR15: 28.500034 | AS15: 28.604715 | AT15: 28.356279 | AU15: 27.404783 | AV15: 28.277628 | AW15: 28.361124 | AX15: 28.350717 | AY15: 29.925943 | AZ15: 29.893178 | BA15: 30.408889 | BB15: 31.133768 | BC15: 31.157896 | BD15: 31.340799 | BE15: 31.790911 | BF15: 32.025014 | BG15: 31.215274 | BH15: 33.000802 | BI15: 32.546824 | BJ15: 32.772151 | BK15: 32.807918 | BL15: 33.90826
A16: 18 | B16: '064 | C16: Bhutan | D16: 0.1726 | E16: 0.177935 | F16: 0.18345 | G16: 0.188185 | H16: 0.192925 | I16: 0.19794 | J16: 0.203569 | K16: 0.21036 | L16: 0.21513 | M16: 0.220105 | N16: 0.225415 | O16: 0.230285 | P16: 0.235415 | Q16: 0.240485 | R16: 0.244868 | S16: 0.250598 | T16: 0.25505 | U16: 0.2612 | V16: 0.26906 | W16: 0.27856 | X16: 0.283755 | Y16: 0.290926 | Z16: 0.30369 | AA16: 0.317341 | AB16: 0.30743 | AC16: 0.308725 | AD16: 0.314615 | AE16: 0.250358 | AF16: 0.252835 | AG16: 0.260581 | AH16: 0.277041 | AI16: 0.273631 | AJ16: 0.283962 | AK16: 0.285562 | AL16: 0.296132 | AM16: 0.29468 | AN16: 0.287307 | AO16: 0.279943 | AP16: 0.265962 | AQ16: 0.213471 | AR16: 0.228683 | AS16: 0.190902 | AT16: 0.178393 | AU16: 0.160539 | AV16: 0.26052 | AW16: 0.27159 | AX16: 0.294554 | AY16: 0.212944 | AZ16: 0.206018 | BA16: 0.186007 | BB16: 0.228921 | BC16: 0.187321 | BD16: 0.182446 | BE16: 0.178202 | BF16: 0.161313 | BG16: 0.178507 | BH16: 0.188817 | BI16: 0.135873 | BJ16: 0.128841 | BK16: 0.122855 | BL16: 0.097688
A17: 19 | B17: '068 | C17: Bolivia (Plurinational State of) | D17: 1.408808 | E17: 1.448998 | F17: 1.550282 | G17: 1.571153 | H17: 1.49723 | I17: 1.519199 | J17: 1.439191 | K17: 1.538384 | L17: 1.562554 | M17: 1.55228 | N17: 1.58156 | O17: 1.652255 | P17: 1.724517 | Q17: 1.780585 | R17: 1.913905 | S17: 1.962315 | T17: 2.011992 | U17: 1.99214 | V17: 2.034059 | W17: 2.11684 | X17: 2.195645 | Y17: 2.119631 | Z17: 1.737409 | AA17: 2.391031 | AB17: 2.681898 | AC17: 2.505733 | AD17: 2.483789 | AE17: 2.453535 | AF17: 2.450785 | AG17: 2.416507 | AH17: 3.163746 | AI17: 3.350094 | AJ17: 3.363095 | AK17: 3.588726 | AL17: 4.087967 | AM17: 4.314265 | AN17: 4.638784 | AO17: 5.175888 | AP17: 5.207563 | AQ17: 4.958958 | AR17: 4.959767 | AS17: 5.24118 | AT17: 5.071243 | AU17: 5.572299 | AV17: 6.229739 | AW17: 6.316289 | AX17: 6.610748 | AY17: 6.326121 | AZ17: 7.228867 | BA17: 7.252673 | BB17: 7.62285 | BC17: 8.155123 | BD17: 8.854594 | BE17: 8.616343 | BF17: 8.57009 | BG17: 8.713994 | BH17: 8.32927 | BI17: 9.020061 | BJ17: 9.195062 | BK17: 9.211062 | BL17: 9.537572
A18: 20 | B18: '072 | C18: Botswana | D18: 0.433431 | E18: 0.160082 | F18: 0.1591 | G18: 0.145367 | H18: 0.13101 | I18: 0.223336 | J18: 0.477535 | K18: 0.264393 | L18: 0.389815 | M18: 0.430959 | N18: 0.509558 | O18: 0.245878 | P18: 0.32926 | Q18: 0.3995 | R18: 0.39153 | S18: 0.47496 | T18: 0.44935 | U18: 0.35078 | V18: 0.24108 | W18: 0.48368 | X18: 0.48718 | Y18: 0.223971 | Z18: 0.21461 | AA18: 0.21661 | AB18: 0.29531 | AC18: 0.32631 | AD18: 0.34381 | AE18: 0.66541 | AF18: 0.62731 | AG18: 0.505857 | AH18: 0.333503 | AI18: 0.212895 | AJ18: 0.277805 | AK18: 0.556168 | AL18: 0.334364 | AM18: 0.621594 | AN18: 0.397573 | AO18: 0.195118 | AP18: 0.260777 | AQ18: 0.39758 | AR18: 0.163763 | AS18: 0.272908 | AT18: 0.134999 | AU18: 0.270075 | AV18: 0.241391 | AW18: 0.294312 | AX18: 0.144784 | AY18: 0.29202 | AZ18: 0.389633 | BA18: 0.361522 | BB18: 0.444209 | BC18: 0.27802 | BD18: 0.256831 | BE18: 0.41811 | BF18: 0.161382 | BG18: 0.281949 | BH18: 0.216183 | BI18: 0.41208 | BJ18: 0.213928 | BK18: 0.449045 | BL18: 0.363788
A19: 21 | B19: '076 | C19: Brazil | D19: 44.768595 | E19: 46.679628 | F19: 49.694648 | G19: 51.039987 | H19: 54.23886 | I19: 52.467211 | J19: 57.034237 | K19: 58.516006 | L19: 60.196828 | M19: 62.488098 | N19: 65.904066 | O19: 65.81669 | P19: 66.211848 | Q19: 70.351265 | R19: 73.462418 | S19: 77.031632 | T19: 80.099707 | U19: 78.610629 | V19: 80.596253 | W19: 82.839069 | X19: 81.581083 | Y19: 87.334209 | Z19: 76.056117 | AA19: 83.357098 | AB19: 86.091948 | AC19: 91.149386 | AD19: 92.229856 | AE19: 94.151763 | AF19: 92.55963 | AG19: 85.404003 | AH19: 114.25664 | AI19: 114.56 | AJ19: 105.98232 | AK19: 116.79722 | AL19: 116.00853 | AM19: 103.48578 | AN19: 108.1531 | AO19: 108.78433 | AP19: 112.61616 | AQ19: 115.79277 | AR19: 116.41605 | AS19: 124.27164 | AT19: 135.31566 | AU19: 147.80937 | AV19: 150.77521 | AW19: 146.51454 | AX19: 146.25759 | AY19: 152.84387 | AZ19: 152.78891 | BA19: 154.36711 | BB19: 161.61557 | BC19: 162.70504 | BD19: 172.54028 | BE19: 183.44254 | BF19: 186.13083 | BG19: 185.77091 | BH19: 191.90927 | BI19: 192.57192 | BJ19: 200.41835 | BK19: 206.56506 | BL19: 213.45743
A20: 23 | B20: '084 | C20: Belize | D20: 0.033813 | E20: 0.027536 | F20: 0.030372 | G20: 0.037183 | H20: 0.041694 | I20: 0.046137 | J20: 0.053791 | K20: 0.065584 | L20: 0.059613 | M20: 0.067309 | N20: 0.068429 | O20: 0.073182 | P20: 0.069399 | Q20: 0.081291 | R20: 0.089659 | S20: 0.09489 | T20: 0.09219 | U20: 0.092128 | V20: 0.089704 | W20: 0.100647 | X20: 0.104676 | Y20: 0.103779 | Z20: 0.091696 | AA20: 0.095232 | AB20: 0.101982 | AC20: 0.098706 | AD20: 0.112864 | AE20: 0.110584 | AF20: 0.140714 | AG20: 0.145417 | AH20: 0.17072 | AI20: 0.179387 | AJ20: 0.197348 | AK20: 0.146107 | AL20: 0.178249 | AM20: 0.17455 | AN20: 0.193035 | AO20: 0.194863 | AP20: 0.207618 | AQ20: 0.186297 | AR20: 0.178424 | AS20: 0.174315 | AT20: 0.167501 | AU20: 0.17091 | AV20: 0.177393 | AW20: 0.164225 | AX20: 0.181227 | AY20: 0.187323 | AZ20: 0.199765 | BA20: 0.197646 | BB20: 0.200823 | BC20: 0.200518 | BD20: 0.217576 | BE20: 0.212086 | BF20: 0.231215 | BG20: 0.225283 | BH20: 0.235698 | BI20: 0.237089 | BJ20: 0.2368 | BK20: 0.257733 | BL20: 0.253123
A21: 25 | B21: '090 | C21: Solomon Islands | D21: 0.047658 | E21: 0.046838 | F21: 0.048997 | G21: 0.049248 | H21: 0.04944 | I21: 0.047927 | J21: 0.048038 | K21: 0.046625 | L21: 0.052034 | M21: 0.051814 | N21: 0.052942 | O21: 0.051516 | P21: 0.051686 | Q21: 0.052034 | R21: 0.053088 | S21: 0.054757 | T21: 0.058108 | U21: 0.06047 | V21: 0.066826 | W21: 0.068789 | X21: 0.069795 | Y21: 0.067522 | Z21: 0.067818 | AA21: 0.06918 | AB21: 0.072066 | AC21: 0.073188 | AD21: 0.070848 | AE21: 0.074585 | AF21: 0.07273 | AG21: 0.076205 | AH21: 0.158032 | AI21: 0.166587 | AJ21: 0.167204 | AK21: 0.167714 | AL21: 0.170636 | AM21: 0.168233 | AN21: 0.17123 | AO21: 0.171799 | AP21: 0.171401 | AQ21: 0.176814 | AR21: 0.176018 | AS21: 0.179245 | AT21: 0.184435 | AU21: 0.185017 | AV21: 0.221343 | AW21: 0.229099 | AX21: 0.238615 | AY21: 0.233944 | AZ21: 0.24149 | BA21: 0.208524 | BB21: 0.214493 | BC21: 0.217731 | BD21: 0.222211 | BE21: 0.226398 | BF21: 0.228465 | BG21: 0.231588 | BH21: 0.235243 | BI21: 0.238783 | BJ21: 0.241448 | BK21: 0.25492 | BL21: 0.26889
A22: 26 | B22: '096 | C22: Brunei Darussalam | D22: 0.043604 | E22: 0.041109 | F22: 0.034863 | G22: 0.034347 | H22: 0.035334 | I22: 0.036032 | J22: 0.037978 | K22: 0.037692 | L22: 0.035879 | M22: 0.035607 | N22: 0.03373 | O22: 0.016288 | P22: 0.018336 | Q22: 0.020352 | R22: 0.019432 | S22: 0.019431 | T22: 0.016097 | U22: 0.013185 | V22: 0.012658 | W22: 0.015506 | X22: 0.013716 | Y22: 0.013 | Z22: 0.013391 | AA22: 0.021647 | AB22: 0.019082 | AC22: 0.019029 | AD22: 0.019636 | AE22: 0.019437 | AF22: 0.018829 | AG22: 0.019787 | AH22: 0.01912 | AI22: 0.018451 | AJ22: 0.018383 | AK22: 0.019417 | AL22: 0.021884 | AM22: 0.024046 | AN22: 0.024079 | AO22: 0.023454 | AP22: 0.025881 | AQ22: 0.03109 | AR22: 0.031654 | AS22: 0.033418 | AT22: 0.031416 | AU22: 0.030719 | AV22: 0.029743 | AW22: 0.022363 | AX22: 0.021876 | AY22: 0.022943 | AZ22: 0.024413 | BA22: 0.025169 | BB22: 0.025138 | BC22: 0.026181 | BD22: 0.025632 | BE22: 0.025308 | BF22: 0.021741 | BG22: 0.024908 | BH22: 0.024505 | BI22: 0.023487 | BJ22: 0.023946 | BK22: 0.023605 | BL22: 0.023402
A23: 27 | B23: '100 | C23: Bulgaria | D23: 7.056254 | E23: 6.904297 | F23: 6.859493 | G23: 7.025803 | H23: 6.671298 | I23: 6.701604 | J23: 6.424264 | K23: 6.231674 | L23: 6.104398 | M23: 6.114929 | N23: 6.144148 | O23: 6.107033 | P23: 5.833451 | Q23: 5.887777 | R23: 6.182043 | S23: 6.187284 | T23: 6.151173 | U23: 5.898998 | V23: 5.995043 | W23: 5.682175 | X23: 5.791532 | Y23: 5.885008 | Z23: 5.794658 | AA23: 5.652724 | AB23: 5.282922 | AC23: 5.730461 | AD23: 5.442578 | AE23: 5.686597 | AF23: 5.766498 | AG23: 5.549679 | AH23: 6.579796 | AI23: 7.051579 | AJ23: 6.937474 | AK23: 7.091825 | AL23: 7.136939 | AM23: 6.081935 | AN23: 6.475929 | AO23: 6.732876 | AP23: 6.410203 | AQ23: 6.17587 | AR23: 6.307498 | AS23: 6.556211 | AT23: 6.038345 | AU23: 6.242491 | AV23: 5.992438 | AW23: 5.983896 | AX23: 5.613364 | AY23: 6.352828 | AZ23: 6.500289 | BA23: 6.875754 | BB23: 6.923061 | BC23: 6.91796 | BD23: 7.389626 | BE23: 7.306511 | BF23: 7.112176 | BG23: 7.090395 | BH23: 7.163254 | BI23: 5.051857 | BJ23: 5.124921 | BK23: 5.15002 | BL23: 5.16202
A24: 28 | B24: '104 | C24: Myanmar | D24: 11.933715 | E24: 13.109983 | F24: 13.948517 | G24: 14.120862 | H24: 13.998816 | I24: 13.262518 | J24: 13.58269 | K24: 13.777002 | L24: 13.605868 | M24: 13.856716 | N24: 13.989639 | O24: 13.66257 | P24: 14.087748 | Q24: 14.310594 | R24: 14.566235 | S24: 14.301662 | T24: 14.097157 | U24: 14.581686 | V24: 13.93496 | W24: 14.028571 | X24: 14.599453 | Y24: 14.11637 | Z24: 14.647334 | AA24: 14.70562 | AB24: 15.170845 | AC24: 15.154566 | AD24: 14.235498 | AE24: 14.014356 | AF24: 14.229529 | AG24: 14.82928 | AH24: 17.820047 | AI24: 20.08197 | AJ24: 21.007945 | AK24: 22.401968 | AL24: 23.813125 | AM24: 24.100182 | AN24: 22.714 | AO24: 22.920964 | AP24: 27.511848 | AQ24: 29.400552 | AR24: 30.009127 | AS24: 30.736114 | AT24: 31.920128 | AU24: 32.869072 | AV24: 34.3448 | AW24: 37.445153 | AX24: 38.016074 | AY24: 39.785521 | AZ24: 40.330715 | BA24: 40.217824 | BB24: 38.246226 | BC24: 37.010632 | BD24: 37.674574 | BE24: 37.823016 | BF24: 37.964426 | BG24: 37.672834 | BH24: 37.187004 | BI24: 36.858474 | BJ24: 36.43655 | BK24: 35.98474 | BL24: 35.202913
A25: 29 | B25: '108 | C25: Burundi | D25: 1.528426 | E25: 1.506136 | F25: 1.555018 | G25: 1.639295 | H25: 1.673753 | I25: 1.687522 | J25: 1.73619 | K25: 1.767076 | L25: 1.685764 | M25: 1.716609 | N25: 1.740684 | O25: 1.66425 | P25: 1.779996 | Q25: 1.630269 | R25: 1.799049 | S25: 1.81267 | T25: 1.838841 | U25: 1.771792 | V25: 1.831455 | W25: 1.962092 | X25: 1.929046 | Y25: 2.020284 | Z25: 2.017595 | AA25: 1.897244 | AB25: 2.156775 | AC25: 2.231696 | AD25: 2.306802 | AE25: 2.369862 | AF25: 2.198056 | AG25: 2.219662 | AH25: 2.380198 | AI25: 2.420134 | AJ25: 2.38073 | AK25: 2.054851 | AL25: 2.217791 | AM25: 2.256299 | AN25: 2.265022 | AO25: 2.227038 | AP25: 2.170329 | AQ25: 2.118537 | AR25: 2.326695 | AS25: 2.515387 | AT25: 2.352424 | AU25: 2.479124 | AV25: 2.384049 | AW25: 2.377023 | AX25: 2.235349 | AY25: 2.348943 | AZ25: 2.365653 | BA25: 2.495981 | BB25: 2.459679 | BC25: 2.665095 | BD25: 2.670946 | BE25: 2.634585 | BF25: 2.708954 | BG25: 2.968165 | BH25: 3.135152 | BI25: 3.441976 | BJ25: 4.237267 | BK25: 4.328824 | BL25: 3.767048
A26: 32 | B26: '120 | C26: Cameroon | D26: 3.532028 | E26: 3.80317 | F26: 4.017264 | G26: 3.977009 | H26: 3.857372 | I26: 3.944575 | J26: 4.1792 | K26: 4.249594 | L26: 4.447664 | M26: 4.604254 | N26: 4.872977 | O26: 4.753472 | P26: 4.965713 | Q26: 5.222452 | R26: 5.452146 | S26: 5.219595 | T26: 5.249253 | U26: 5.307076 | V26: 5.31543 | W26: 5.308691 | X26: 5.153537 | Y26: 5.493351 | Z26: 5.623191 | AA26: 4.613288 | AB26: 4.997108 | AC26: 5.325711 | AD26: 4.334184 | AE26: 4.770935 | AF26: 4.696286 | AG26: 4.524702 | AH26: 6.210113 | AI26: 6.512095 | AJ26: 6.925937 | AK26: 7.178144 | AL26: 7.511803 | AM26: 7.557629 | AN26: 7.490411 | AO26: 7.890455 | AP26: 6.775485 | AQ26: 7.14303 | AR26: 7.431531 | AS26: 8.197885 | AT26: 8.630128 | AU26: 8.866428 | AV26: 8.722829 | AW26: 9.082314 | AX26: 9.430526 | AY26: 9.674517 | AZ26: 10.837098 | BA26: 11.768393 | BB26: 12.102304 | BC26: 12.476197 | BD26: 12.699782 | BE26: 13.016739 | BF26: 13.828145 | BG26: 14.027765 | BH26: 13.507481 | BI26: 14.009791 | BJ26: 14.151619 | BK26: 14.103481 | BL26: 14.163854
... A40: 50 | B40: '196 | C40: Cyprus | D40: 0.527892 | E40: 0.531381 | F40: 0.544713 | G40: 0.539232 | H40: 0.544677 | I40: 0.543732 | J40: 0.555113 | K40: 0.578765 | L40: 0.572874 | M40: 0.618622 | N40: 0.644156 | O40: 0.618942 | P40: 0.636615 | Q40: 0.605262 | R40: 0.330699 | S40: 0.35119 | T40: 0.351899 | U40: 0.256534 | V40: 0.254364 | W40: 0.260455 | X40: 0.2583 | Y40: 0.263031 | Z40: 0.264937 | AA40: 0.268315 | AB40: 0.249436 | AC40: 0.244761 | AD40: 0.248772 | AE40: 0.256271 | AF40: 0.255436 | AG40: 0.247891 | AH40: 0.234102 | AI40: 0.265632 | AJ40: 0.267864 | AK40: 0.245601 | AL40: 0.246154 | AM40: 0.242301 | AN40: 0.203841 | AO40: 0.235809 | AP40: 0.233319 | AQ40: 0.215936 | AR40: 0.222719 | AS40: 0.225136 | AT40: 0.253767 | AU40: 0.25119 | AV40: 0.229628 | AW40: 0.216253 | AX40: 0.177388 | AY40: 0.158257 | AZ40: 0.154815 | BA40: 0.144285 | BB40: 0.152599 | BC40: 0.152866 | BD40: 0.133967 | BE40: 0.125328 | BF40: 0.139304 | BG40: 0.12084 | BH40: 0.109065 | BI40: 0.105382 | BJ40: 0.103582 | BK40: 0.121134 | BL40: 0.1077
A41: 51 | B41: '200 | C41: Czechoslovakia | D41: 7.12133 | E41: 7.213353 | F41: 7.22195 | G41: 7.30988 | H41: 6.481888 | I41: 7.079724 | J41: 7.021938 | K41: 6.959797 | L41: 6.875653 | M41: 6.735871 | N41: 6.827301 | O41: 6.936736 | P41: 6.927205 | Q41: 6.867855 | R41: 6.894012 | S41: 6.649873 | T41: 6.815633 | U41: 6.726595 | V41: 6.56074 | W41: 6.506017 | X41: 6.520717 | Y41: 6.496879 | Z41: 6.482385 | AA41: 6.433506 | AB41: 6.706343 | AC41: 6.69092 | AD41: 6.673347 | AE41: 6.575116 | AF41: 6.629786 | AG41: 6.476162 | AH41: 7.114591 | AI41: 7.076819
A42: 52 | B42: '031 | C42: Azerbaijan | AI42: 2.820582 | AJ42: 2.913904 | AK42: 2.669981 | AL42: 2.567831 | AM42: 2.596622 | AN42: 2.577505 | AO42: 2.184724 | AP42: 1.850476 | AQ42: 2.208609 | AR42: 2.414343 | AS42: 2.450471 | AT42: 2.405402 | AU42: 2.548814 | AV42: 2.693585 | AW42: 2.614682 | AX42: 2.445705 | AY42: 2.64223 | AZ42: 2.970738 | BA42: 2.7173 | BB42: 2.786916 | BC42: 2.848245 | BD42: 2.914712 | BE42: 2.755104 | BF42: 2.665221 | BG42: 2.893776 | BH42: 3.216802 | BI42: 3.403453 | BJ42: 3.273126 | BK42: 3.091777 | BL42: 3.130217
A43: 53 | B43: '204 | C43: Benin | D43: 1.821325 | E43: 1.896519 | F43: 1.82923 | G43: 1.745827 | H43: 1.732673 | I43: 1.657986 | J43: 1.806657 | K43: 1.758773 | L43: 1.776633 | M43: 1.822032 | N43: 1.671673 | O43: 1.71601 | P43: 1.692623 | Q43: 1.599368 | R43: 1.418742 | S43: 1.439567 | T43: 1.552495 | U43: 1.957063 | V43: 1.917274 | W43: 1.701093 | X43: 1.871772 | Y43: 1.87374 | Z43: 1.946554 | AA43: 2.062376 | AB43: 2.198763 | AC43: 2.191941 | AD43: 2.032526 | AE43: 2.409007 | AF43: 2.40049 | AG43: 2.434801 | AH43: 3.330167 | AI43: 3.239102 | AJ43: 3.420525 | AK43: 3.639805 | AL43: 4.081382 | AM43: 4.665914 | AN43: 5.065186 | AO43: 5.201304 | AP43: 5.283672 | AQ43: 5.345069 | AR43: 5.28678 | AS43: 5.639043 | AT43: 5.473532 | AU43: 5.581836 | AV43: 5.216716 | AW43: 4.975109 | AX43: 5.199849 | AY43: 6.123846 | AZ43: 6.128504 | BA43: 5.989112 | BB43: 5.959603 | BC43: 7.052763 | BD43: 7.632172 | BE43: 7.923103 | BF43: 7.891513 | BG43: 7.827783 | BH43: 8.599725 | BI43: 9.80934 | BJ43: 10.209046 | BK43: 9.650929 | BL43: 10.324299
A44: 54 | B44: '208 | C44: Denmark | D44: 3.383094 | E44: 3.391456 | F44: 3.483647 | G44: 3.490639 | H44: 3.466791 | I44: 3.467778 | J44: 3.528979 | K44: 3.6205 | L44: 3.671419 | M44: 3.740774 | N44: 3.774146 | O44: 3.804078 | P44: 3.799038 | Q44: 3.760623 | R44: 3.777433 | S44: 3.888745 | T44: 3.962559 | U44: 3.997735 | V44: 4.012754 | W44: 3.985265 | X44: 3.965451 | Y44: 3.958458 | Z44: 3.83993 | AA44: 3.932756 | AB44: 3.92831 | AC44: 3.923847 | AD44: 3.890515 | AE44: 3.911088 | AF44: 3.843862 | AG44: 3.891746 | AH44: 4.427723 | AI44: 4.259493 | AJ44: 3.89511 | AK44: 3.788645 | AL44: 3.780253 | AM44: 3.779387 | AN44: 3.834712 | AO44: 3.876835 | AP44: 3.851075 | AQ44: 3.645488 | AR44: 3.606615 | AS44: 3.613651 | AT44: 3.555776 | AU44: 3.611154 | AV44: 3.590809 | AW44: 3.577892 | AX44: 3.64061 | AY44: 3.740957 | AZ44: 3.692293 | BA44: 3.729376 | BB44: 3.66363 | BC44: 3.603117 | BD44: 3.622779 | BE44: 3.606606 | BF44: 3.691307 | BG44: 3.656424 | BH44: 3.67503 | BI44: 3.241 | BJ44: 3.1588 | BK44: 3.1553 | BL44: 3.15508
A45: 55 | B45: '212 | C45: Dominica | D45: 0.013764 | E45: 0.013642 | F45: 0.015774 | G45: 0.017866 | H45: 0.01786 | I45: 0.022148 | J45: 0.01902 | K45: 0.01909 | L45: 0.01924 | M45: 0.01654 | N45: 0.01649 | O45: 0.01683 | P45: 0.01506 | Q45: 0.01728 | R45: 0.017612 | S45: 0.01878 | T45: 0.02003 | U45: 0.02284 | V45: 0.01765 | W45: 0.014326 | X45: 0.015812 | Y45: 0.016146 | Z45: 0.01733 | AA45: 0.016404 | AB45: 0.035208 | AC45: 0.038467 | AD45: 0.043546 | AE45: 0.048005 | AF45: 0.045913 | AG45: 0.040121 | AH45: 0.043898 | AI45: 0.046103 | AJ45: 0.046321 | AK45: 0.043783 | AL45: 0.040254 | AM45: 0.047106 | AN45: 0.049293 | AO45: 0.047014 | AP45: 0.046932 | AQ45: 0.046646 | AR45: 0.04367 | AS45: 0.043756 | AT45: 0.037961 | AU45: 0.040707 | AV45: 0.040859 | AW45: 0.042664 | AX45: 0.043228 | AY45: 0.040221 | AZ45: 0.040392 | BA45: 0.047877 | BB45: 0.040403 | BC45: 0.041746 | BD45: 0.0425 | BE45: 0.044124 | BF45: 0.04825 | BG45: 0.054905 | BH45: 0.049842 | BI45: 0.048963 | BJ45: 0.049214 | BK45: 0.049447 | BL45: 0.049198
A46: 56 | B46: '214 | C46: Dominican Republic | D46: 1.118686 | E46: 1.162035 | F46: 1.081679 | G46: 1.099675 | H46: 1.04889 | I46: 1.130058 | J46: 1.123617 | K46: 1.12029 | L46: 1.242654 | M46: 1.276259 | N46: 1.324504 | O46: 1.33352 | P46: 1.392476 | Q46: 1.412639 | R46: 1.374428 | S46: 1.47869 | T46: 1.460994 | U46: 1.514109 | V46: 1.432493 | W46: 1.468635 | X46: 1.480215 | Y46: 1.450861 | Z46: 1.529272 | AA46: 1.634938 | AB46: 1.697987 | AC46: 1.59287 | AD46: 1.702636 | AE46: 1.705763 | AF46: 1.793632 | AG46: 1.511202 | AH46: 1.696555 | AI46: 1.681599 | AJ46: 1.720265 | AK46: 1.626784 | AL46: 1.780992 | AM46: 1.700746 | AN46: 1.665686 | AO46: 1.705283 | AP46: 1.495778 | AQ46: 1.539845 | AR46: 1.614464 | AS46: 1.588984 | AT46: 1.47675 | AU46: 1.425726 | AV46: 1.482518 | AW46: 1.492035 | AX46: 1.53561 | AY46: 1.494066 | AZ46: 1.585707 | BA46: 1.587524 | BB46: 1.705355 | BC46: 1.606221 | BD46: 1.651325 | BE46: 1.659753 | BF46: 1.641278 | BG46: 1.849436 | BH46: 1.888208 | BI46: 1.964928 | BJ46: 1.976439 | BK46: 1.87543 | BL46: 1.867325
A47: 57 | B47: '112 | C47: Belarus | AI47: 8.1596 | AJ47: 7.942686 | AK47: 7.846768 | AL47: 8.005646 | AM47: 7.791928 | AN47: 7.841134 | AO47: 7.827637 | AP47: 7.676616 | AQ47: 7.688606 | AR47: 7.812356 | AS47: 7.15012 | AT47: 6.685974 | AU47: 7.114337 | AV47: 6.842286 | AW47: 6.919494 | AX47: 7.416303 | AY47: 7.757315 | AZ47: 7.77127 | BA47: 7.538823 | BB47: 7.547531 | BC47: 8.116442 | BD47: 7.698804 | BE47: 7.750281 | BF47: 6.767702 | BG47: 6.616449 | BH47: 7.026346 | BI47: 6.876218 | BJ47: 7.076142 | BK47: 7.216731 | BL47: 7.374936
A48: 58 | B48: '218 | C48: Ecuador | D48: 2.301199 | E48: 2.416153 | F48: 2.523958 | G48: 2.834434 | H48: 3.015287 | I48: 2.945352 | J48: 3.207518 | K48: 3.012869 | L48: 2.943731 | M48: 2.914962 | N48: 2.907298 | O48: 2.87252 | P48: 2.644081 | Q48: 2.752777 | R48: 2.773872 | S48: 2.81597 | T48: 2.655372 | U48: 2.256745 | V48: 2.331498 | W48: 2.469954 | X48: 2.568166 | Y48: 2.477108 | Z48: 2.253349 | AA48: 2.516823 | AB48: 2.603951 | AC48: 3.617545 | AD48: 3.71662 | AE48: 3.685282 | AF48: 3.734422 | AG48: 3.750185 | AH48: 3.664427 | AI48: 4.624638 | AJ48: 4.679002 | AK48: 4.844792 | AL48: 4.80126 | AM48: 4.793458 | AN48: 4.787059 | AO48: 3.998133 | AP48: 4.389343 | AQ48: 4.670825 | AR48: 4.638365 | AS48: 4.576796 | AT48: 4.518649 | AU48: 4.659356 | AV48: 4.458538 | AW48: 4.304748 | AX48: 4.431982 | AY48: 4.337492 | AZ48: 4.691991 | BA48: 4.730171 | BB48: 4.901556 | BC48: 4.623276 | BD48: 4.782386 | BE48: 4.626594 | BF48: 4.644608 | BG48: 4.271342 | BH48: 4.376386 | BI48: 4.084911 | BJ48: 4.04716 | BK48: 4.120303 | BL48: 4.120736
A49: 59 | B49: '818 | C49: Egypt | D49: 5.539922 | E49: 5.992354 | F49: 6.0023 | G49: 6.001058 | H49: 5.57697 | I49: 5.943839 | J49: 5.899256 | K49: 6.25079 | L49: 6.134587 | M49: 6.079796 | N49: 6.076379 | O49: 6.115174 | P49: 6.123355 | Q49: 6.327365 | R49: 6.43252 | S49: 6.585958 | T49: 6.347695 | U49: 6.477155 | V49: 6.53792 | W49: 6.477126 | X49: 6.473678 | Y49: 6.547526 | Z49: 6.543545 | AA49: 6.428972 | AB49: 6.480207 | AC49: 6.617655 | AD49: 6.754023 | AE49: 6.886682 | AF49: 7.109388 | AG49: 7.42195 | AH49: 9.093305 | AI49: 9.246403 | AJ49: 9.375146 | AK49: 9.220495 | AL49: 9.768194 | AM49: 9.823004 | AN49: 10.064945 | AO49: 9.91858 | AP49: 10.059534 | AQ49: 9.981298 | AR49: 10.075828 | AS49: 10.249043 | AT49: 10.120284 | AU49: 10.470125 | AV49: 10.898997 | AW49: 10.951954 | AX49: 11.017588 | AY49: 10.988398 | AZ49: 11.143748 | BA49: 10.943933 | BB49: 11.312961 | BC49: 11.53557 | BD49: 11.490885 | BE49: 11.802537 | BF49: 11.681028 | BG49: 11.302433 | BH49: 11.290889 | BI49: 10.340002 | BJ49: 12.352175 | BK49: 11.715572 | BL49: 11.466268
A50: 60 | B50: '222 | C50: El Salvador | D50: 0.923237 | E50: 0.981845 | F50: 0.930695 | G50: 0.92718 | H50: 1.040074 | I50: 1.062585 | J50: 1.010587 | K50: 1.022078 | L50: 0.990156 | M50: 1.055736 | N50: 1.12378 | O50: 1.128726 | P50: 1.109858 | Q50: 1.181711 | R50: 1.291108 | S50: 1.226219 | T50: 1.267591 | U50: 1.338063 | V50: 1.40743 | W50: 1.384982 | X50: 1.276629 | Y50: 1.232883 | Z50: 1.224908 | AA50: 1.238759 | AB50: 1.279827 | AC50: 1.290807 | AD50: 1.326751 | AE50: 1.325941 | AF50: 1.290561 | AG50: 1.357265 | AH50: 1.565805 | AI50: 1.605573 | AJ50: 1.529696 | AK50: 1.511089 | AL50: 1.440109 | AM50: 1.404385 | AN50: 1.527581 | AO50: 1.463531 | AP50: 1.388801 | AQ50: 1.336465 | AR50: 1.4114 | AS50: 1.229456 | AT50: 1.226691 | AU50: 1.250213 | AV50: 1.262849 | AW50: 1.260104 | AX50: 1.241855 | AY50: 1.376923 | AZ50: 1.368013 | BA50: 1.333368 | BB50: 1.35579 | BC50: 1.455987 | BD50: 1.433724 | BE50: 1.474173 | BF50: 1.402876 | BG50: 1.452028 | BH50: 1.327601 | BI50: 1.305737 | BJ50: 1.282314 | BK50: 1.280037 | BL50: 1.372546
A51: 61 | B51: '226 | C51: Equatorial Guinea | D51: 0.1519 | E51: 0.1534 | F51: 0.1465 | G51: 0.147 | H51: 0.1465 | I51: 0.1506 | J51: 0.1536 | K51: 0.17 | L51: 0.16 | M51: 0.16 | N51: 0.1622 | O51: 0.1404 | P51: 0.1364 | Q51: 0.1349 | R51: 0.1354 | S51: 0.1349 | T51: 0.1339 | U51: 0.1359 | V51: 0.1359 | W51: 0.1378 | X51: 0.1379 | Y51: 0.1434 | Z51: 0.1407 | AA51: 0.145 | AB51: 0.15 | AC51: 0.1522 | AD51: 0.1542 | AE51: 0.1542 | AF51: 0.1543 | AG51: 0.16304 | AH51: 0.186761 | AI51: 0.197606 | AJ51: 0.168571 | AK51: 0.182752 | AL51: 0.171517 | AM51: 0.178275 | AN51: 0.179541 | AO51: 0.165717 | AP51: 0.175477 | AQ51: 0.176349 | AR51: 0.175601 | AS51: 0.158955 | AT51: 0.166097 | AU51: 0.173297 | AV51: 0.174241 | AW51: 0.16682 | AX51: 0.175192 | AY51: 0.17195 | AZ51: 0.164817 | BA51: 0.167347 | BB51: 0.167876 | BC51: 0.16564 | BD51: 0.167043 | BE51: 0.169458 | BF51: 0.17414 | BG51: 0.173832 | BH51: 0.176139 | BI51: 0.179075 | BJ51: 0.180216 | BK51: 0.180272 | BL51: 0.176752
A52: 62 | B52: '230 | C52: Ethiopia PDR | D52: 15.3472 | E52: 15.997 | F52: 16.13466 | G52: 16.25713 | H52: 16.45285 | I52: 16.64235 | J52: 16.838 | K52: 17.08377 | L52: 17.30757 | M52: 17.5468 | N52: 17.80843 | O52: 17.31906 | P52: 15.12795 | Q52: 15.124068 | R52: 13.35915 | S52: 12.866914 | T52: 12.544456 | U52: 12.90558 | V52: 13.329593 | W52: 14.549527 | X52: 13.693152 | Y52: 13.707481 | Z52: 14.480622 | AA52: 13.695333 | AB52: 14.109978 | AC52: 14.333262 | AD52: 14.060797 | AE52: 14.531458 | AF52: 14.079212 | AG52: 14.316497 | AH52: 14.945415 | AI52: 14.673054
A53: 63 | B53: '233 | C53: Estonia | AI53: 0.997142 | AJ53: 0.877136 | AK53: 0.766058 | AL53: 0.743041 | AM53: 0.718177 | AN53: 0.798362 | AO53: 0.872414 | AP53: 0.814241 | AQ53: 0.846414 | AR53: 0.727254 | AS53: 0.695834 | AT53: 0.746735 | AU53: 0.753735 | AV53: 0.771663 | AW53: 0.805935 | AX53: 0.862984 | AY53: 0.901149 | AZ53: 0.930353 | BA53: 0.899341 | BB53: 0.917344 | BC53: 0.899945 | BD53: 0.940615 | BE53: 0.976407 | BF53: 1.00775 | BG53: 1.054956 | BH53: 1.046196 | BI53: 0.88493 | BJ53: 0.90679 | BK53: 0.93069 | BL53: 0.93022
...

Sheet regions_full
A1: polity_code | B1: polity_name | C1: V1 | D1: code | E1: iso3c | F1: FAOSTAT_name | G1: EU27 | H1: name | I1: eia | J1: iea | K1: water_code | L1: water_area | M1: baci | N1: fish | O1: region_code | P1: cbs | Q1: fabio_code | R1: ADB_Region | S1: region | T1: uISO3c | U1: Lassaletta | V1: region_krausmann | W1: region_HANPP | X1: region_krausmann2 | Y1: region_UN_sub | Z1: region_UN | AA1: region_ILO1 | AB1: region_ILO2 | AC1: region_ILO3 | AD1: region_IEA | AE1: region_IPCC | AF1: region_labour | AG1: region_labour_agg | AH1: region_labour_mech | AI1: region_test
B2: =IFERROR(VLOOKUP(A2,polities_whep!$A$1:$G$199,2,0),"") | C2: 30 | D2: 30 | E2: ATA | F2: =VLOOKUP(D2,FAO_areas!$A$2:$C$246,3,0) -> #N/A | G2: FALSE | H2: Antarctica | I2: Antarctica | K2: 999 | L2: Global average | M2: NA | N2: 10 | O2: 19 | P2: FALSE | Q2: 999 | S2: #N/A | T2: 1 | U2: Antarctica | V2: Northern Africa and Western Asia | W2: North Africa and West Asia | X2: MENA
B3: =IFERROR(VLOOKUP(A3,polities_whep!$A$1:$G$199,2,0),"") | C3: 259 | D3: 351 | F3: =VLOOKUP(D3,FAO_areas!$A$2:$C$246,3,0) -> China | G3: FALSE | H3: China | K3: 351 | L3: China | M3: 156 | N3: 156 | O3: 14 | P3: FALSE | S3: East Asia | T3: 1 | U3: China | V3: Eastern Asia | W3: East Asia | X3: S&E Asia
B4: =IFERROR(VLOOKUP(A4,polities_whep!$A$1:$G$199,2,0),"") | C4: 149 | D4: 152 | E4: NTZ | F4: =VLOOKUP(D4,FAO_areas!$A$2:$C$246,3,0) -> #N/A | G4: FALSE | H4: Neutral Zone | K4: 999 | L4: Global average | M4: NA | N4: 536 | O4: 12 | P4: FALSE | Q4: 999 | S4: Middle East | T4: 1 | U4: Neutral Zone | V4: Northern Africa and Western Asia | W4: North Africa and West Asia | X4: MENA | AI4: =IF(Z4="Europe","Europe","Other") -> Other
B5: =IFERROR(VLOOKUP(A5,polities_whep!$A$1:$G$199,2,0),"") | C5: 245 | D5: 254 | E5: OXY | F5: =VLOOKUP(D5,FAO_areas!$A$2:$C$246,3,0) -> #N/A | G5: FALSE | H5: Others (adjustment) | K5: 999 | L5: Global average | M5: NA | N5: NA | O5: NA | P5: FALSE | Q5: 999 | S5: #N/A | T5: 1 | U5: Others (adjustment) | V5: Northern Africa and Western Asia | W5: North Africa and West Asia | X5: MENA
B6: =IFERROR(VLOOKUP(A6,polities_whep!$A$1:$G$199,2,0),"") | C6: 260 | D6: 999 | E6: ROW | F6: =VLOOKUP(D6,FAO_areas!$A$2:$C$246,3,0) -> #N/A | G6: FALSE | H6: RoW | K6: 999 | L6: Global average | M6: NA | N6: NA | O6: NA | P6: TRUE | Q6: 999 | S6: #N/A | T6: 1 | U6: RoW | V6: Northern Africa and Western Asia | W6: North Africa and West Asia | X6: RoW | Y6: RoW | Z6: RoW | AA6: RoW | AB6: RoW | AC6: RoW | AD6: RoW | AE6: RoW | AF6: RoW | AG6: RoW | AH6: RoW | AI6: =IF(Z6="Europe","Europe","Other") -> Other
B7: =IFERROR(VLOOKUP(A7,polities_whep!$A$1:$G$199,2,0),"") | C7: 244 | D7: 252 | E7: UXY | F7: =VLOOKUP(D7,FAO_areas!$A$2:$C$246,3,0) -> #N/A | G7: FALSE | H7: Unspecified | K7: 999 | L7: Global average | M7: NA | N7: 896 | O7: NA | P7: FALSE | Q7: 999 | T7: 1 | U7: Unspecified | V7: Northern Africa and Western Asia | W7: North Africa and West Asia | X7: MENA | AI7: =IF(Z7="Europe","Europe","Other") -> Other
A8: =VLOOKUP(Q8,regions_fabio!$A$2:$C$192,3,0) -> AFG | B8: =IFERROR(VLOOKUP(A8,polities_whep!$A$1:$G$199,2,0),"") -> Afghanistan | C8: 2 | D8: 2 | E8: AFG | F8: =VLOOKUP(D8,FAO_areas!$A$2:$C$246,3,0) -> Afghanistan | G8: FALSE | H8: Afghanistan | I8: Afghanistan | K8: 2 | L8: Afghanistan | M8: 4 | N8: 4 | O8: 13 | P8: TRUE | Q8: 2 | S8: South Asia | T8: 1 | U8: Afghanistan | V8: Southern Asia | W8: South and Central Asia | X8: Southern Asia | Y8: Southern Asia | Z8: Asia | AA8: Asia and the Pacific | AB8: Southern Asia | AC8: Southern Asia | AD8: Emerging | AE8: Annex_II | AF8: Southern Asia | AG8: SE-Asia | AH8: no_mech | AI8: =IF(Z8="Europe","Europe","Other") -> Other
A9: RAFR | B9: =IFERROR(VLOOKUP(A9,polities_whep!$A$1:$G$199,2,0),"") -> Africa Other | C9: 45 | D9: 45 | E9: COM | F9: =VLOOKUP(D9,FAO_areas!$A$2:$C$246,3,0) -> Comoros | G9: FALSE | H9: Comoros | I9: Comoros | K9: 45 | L9: Comoros | M9: 174 | N9: 174 | O9: 7 | P9: FALSE | Q9: 999 | S9: Eastern Africa | T9: 1 | U9: Comoros | V9: Subsaharan Africa | W9: Sub-saharan Africa | X9: SSA | Y9: Sub-Saharan Africa | Z9: Africa | AA9: Africa | AB9: Sub-Saharan Africa | AC9: Eastern Africa | AD9: Emerging | AE9: Annex_II | AF9: Eastern Africa | AG9: SAA | AH9: no_mech | AI9: =IF(Z9="Europe","Europe","Other") -> Other
A10: RAFR | B10: =IFERROR(VLOOKUP(A10,polities_whep!$A$1:$G$199,2,0),"") -> Africa Other | C10: 250 | D10: 270 | E10: MYT | F10: =VLOOKUP(D10,FAO_areas!$A$2:$C$246,3,0) -> #N/A | G10: FALSE | H10: Mayotte | K10: 999 | L10: Global average | M10: 175 | N10: 175 | O10: 7 | P10: FALSE | Q10: 999 | S10: Eastern Africa | T10: 1 | U10: Mayotte | V10: Subsaharan Africa | W10: Sub-saharan Africa | X10: SSA | Y10: Sub-Saharan Africa | Z10: Africa | AA10: Africa | AB10: Sub-Saharan Africa | AC10: Eastern Africa | AD10: Emerging | AE10: Annex_II | AF10: Eastern Africa | AG10: SAA | AH10: no_mech | AI10: =IF(Z10="Europe","Europe","Other") -> Other
A11: RAFR | B11: =IFERROR(VLOOKUP(A11,polities_whep!$A$1:$G$199,2,0),"") -> Africa Other | C11: 179 | D11: 182 | E11: REU | F11: =VLOOKUP(D11,FAO_areas!$A$2:$C$246,3,0) -> Réunion | G11: FALSE | H11: Reunion | I11: Reunion | K11: 182 | L11: Reunion | M11: NA | N11: 638 | O11: 7 | P11: FALSE | Q11: 999 | S11: Eastern Africa | T11: 1 | U11: Reunion | V11: Subsaharan Africa | W11: Sub-saharan Africa | X11: SSA | Y11: Sub-Saharan Africa | Z11: Africa | AA11: Africa | AB11: Sub-Saharan Africa | AC11: Eastern Africa | AD11: Emerging | AE11: Annex_II | AF11: Eastern Africa | AG11: SAA | AH11: no_mech | AI11: =IF(Z11="Europe","Europe","Other") -> Other
A12: RAFR | B12: =IFERROR(VLOOKUP(A12,polities_whep!$A$1:$G$199,2,0),"") -> Africa Other | C12: 184 | D12: 187 | E12: SHN | F12: =VLOOKUP(D12,FAO_areas!$A$2:$C$246,3,0) -> #N/A | G12: FALSE | H12: Saint Helena, Ascension and Tristan da Cunha | I12: Saint Helena | K12: 999 | L12: Global average | M12: 654 | N12: 654 | O12: 6 | P12: FALSE | Q12: 999 | S12: Western Africa | T12: 1 | U12: Saint Helena, Ascension and Tristan da Cunha | V12: Subsaharan Africa | W12: Sub-saharan Africa | X12: SSA | Y12: Sub-Saharan Africa | Z12: Africa | AA12: Africa | AB12: Sub-Saharan Africa | AC12: Western Africa | AD12: Emerging | AE12: Annex_II | AF12: Western Africa | AG12: SAA | AH12: no_mech | AI12: =IF(Z12="Europe","Europe","Other") -> Other
A13: RAFR | B13: =IFERROR(VLOOKUP(A13,polities_whep!$A$1:$G$199,2,0),"") -> Africa Other | C13: 193 | D13: 196 | E13: SYC | F13: =VLOOKUP(D13,FAO_areas!$A$2:$C$246,3,0) -> Seychelles | G13: FALSE | H13: Seychelles | I13: Seychelles | K13: 196 | L13: Seychelles | M13: 690 | N13: 690 | O13: 7 | P13: FALSE | Q13: 999 | S13: Eastern Africa | T13: 1 | U13: Seychelles | V13: Subsaharan Africa | W13: Sub-saharan Africa | X13: SSA | Y13: Sub-Saharan Africa | Z13: Africa | AA13: Africa | AB13: Sub-Saharan Africa | AC13: Eastern Africa | AD13: Emerging | AE13: Annex_II | AF13: Eastern Africa | AG13: SAA | AH13: no_mech | AI13: =IF(Z13="Europe","Europe","Other") -> Other
A14: RAFR | B14: =IFERROR(VLOOKUP(A14,polities_whep!$A$1:$G$199,2,0),"") -> Africa Other | C14: 201 | D14: 205 | E14: ESH | F14: =VLOOKUP(D14,FAO_areas!$A$2:$C$246,3,0) -> #N/A | G14: FALSE | H14: Western Sahara | I14: Western Sahara | K14: 205 | L14: Western Sahara | M14: NA | N14: 732 | O14: 5 | P14: FALSE | Q14: 999 | S14: Northern Africa | T14: 1 | U14: Western Sahara | V14: Northern Africa and Western Asia | W14: North Africa and West Asia | X14: MENA | Y14: Northern Africa | Z14: Africa | AA14: Africa | AB14: Northern Africa | AC14: Northern Africa | AF14: Northern Africa | AG14: MENA | AH14: no_mech | AI14: =IF(Z14="Europe","Europe","Other") -> Other
A15: RAFR | B15: Africa Other
A16: =VLOOKUP(Q16,regions_fabio!$A$2:$C$192,3,0) -> ALB | B16: =IFERROR(VLOOKUP(A16,polities_whep!$A$1:$G$199,2,0),"") -> Albania | C16: 3 | D16: 3 | E16: ALB | F16: =VLOOKUP(D16,FAO_areas!$A$2:$C$246,3,0) -> Albania | G16: FALSE | H16: Albania | I16: Albania | J16: Albania | K16: 3 | L16: Albania | M16: 8 | N16: 8 | O16: 10 | P16: TRUE | Q16: 3 | S16: Eastern Europe | T16: 1 | U16: Albania | V16: Eastern and South Eastern Europe | W16: East Europe | X16: Europe | Y16: Southern Europe | Z16: Europe | AA16: Europe and Central Asia | AB16: Northern, Southern and Western Europe | AC16: Southern Europe | AD16: Emerging | AE16: Annex_II | AF16: Southern Europe | AG16: Europe | AH16: mech | AI16: =IF(Z16="Europe","Europe","Other") -> Europe
A17: =VLOOKUP(Q17,regions_fabio!$A$2:$C$192,3,0) -> DZA | B17: =IFERROR(VLOOKUP(A17,polities_whep!$A$1:$G$199,2,0),"") -> Algeria | C17: 4 | D17: 4 | E17: DZA | F17: =VLOOKUP(D17,FAO_areas!$A$2:$C$246,3,0) -> Algeria | G17: FALSE | H17: Algeria | I17: Algeria | J17: Algeria | K17: 4 | L17: Algeria | M17: 12 | N17: 12 | O17: 5 | P17: TRUE | Q17: 4 | S17: Northern Africa | T17: 1 | U17: Algeria | V17: Northern Africa and Western Asia | W17: North Africa and West Asia | X17: MENA | Y17: Northern Africa | Z17: Africa | AA17: Africa | AB17: Northern Africa | AC17: Northern Africa | AD17: Emerging | AE17: Annex_II | AF17: Northern Africa | AG17: MENA | AH17: no_mech | AI17: =IF(Z17="Europe","Europe","Other") -> Other
A18: =VLOOKUP(Q18,regions_fabio!$A$2:$C$192,3,0) -> AGO | B18: =IFERROR(VLOOKUP(A18,polities_whep!$A$1:$G$199,2,0),"") -> Angola | C18: 7 | D18: 7 | E18: AGO | F18: =VLOOKUP(D18,FAO_areas!$A$2:$C$246,3,0) -> Angola | G18: FALSE | H18: Angola | I18: Angola | J18: Angola | K18: 7 | L18: Angola | M18: 24 | N18: 24 | O18: 8 | P18: TRUE | Q18: 7 | S18: Southern Africa | T18: 1 | U18: Angola | V18: Subsaharan Africa | W18: Sub-saharan Africa | X18: SSA | Y18: Sub-Saharan Africa | Z18: Africa | AA18: Africa | AB18: Sub-Saharan Africa | AC18: Central Africa | AD18: Emerging | AE18: Annex_II | AF18: Middle Africa | AG18: SAA | AH18: Middle Africa | AI18: =IF(Z18="Europe","Europe","Other") -> Other
A19: =VLOOKUP(Q19,regions_fabio!$A$2:$C$192,3,0) -> ATG | B19: =IFERROR(VLOOKUP(A19,polities_whep!$A$1:$G$199,2,0),"") -> Antigua and Barbuda | C19: 8 | D19: 8 | E19: ATG | F19: =VLOOKUP(D19,FAO_areas!$A$2:$C$246,3,0) -> Antigua and Barbuda | G19: FALSE | H19: Antigua and Barbuda | I19: Antigua and Barbuda | K19: 8 | L19: Antigua and Barbuda | M19: 28 | N19: 28 | O19: 3 | P19: TRUE | Q19: 8 | S19: Central America | T19: 1 | U19: Antigua and Barbuda | V19: Latin America and the Caribbean | W19: Latin America and Caribbean | X19: LACA | Y19: Latin America and the Caribbean | Z19: Americas | AA19: Americas | AB19: Latin America and the Caribbean | AC19: Caribbean | AD19: Emerging | AE19: Annex_II | AF19: Caribbean & Centra Am. | AG19: LACA | AH19: no_mech | AI19: =IF(Z19="Europe","Europe","Other") -> Other
A20: =VLOOKUP(Q20,regions_fabio!$A$2:$C$192,3,0) -> ARG | B20: =IFERROR(VLOOKUP(A20,polities_whep!$A$1:$G$199,2,0),"") -> Argentina | C20: 9 | D20: 9 | E20: ARG | F20: =VLOOKUP(D20,FAO_areas!$A$2:$C$246,3,0) -> Argentina | G20: FALSE | H20: Argentina | I20: Argentina | J20: Argentina | K20: 9 | L20: Argentina | M20: 32 | N20: 32 | O20: 4 | P20: TRUE | Q20: 9 | S20: South America | T20: 1 | U20: Argentina | V20: Latin America and the Caribbean | W20: Latin America and Caribbean | X20: LACA | Y20: Latin America and the Caribbean | Z20: Americas | AA20: Americas | AB20: Latin America and the Caribbean | AC20: South America | AD20: Emerging | AE20: Annex_II | AF20: South America - South Cone | AG20: LACA | AH20: mech | AI20: =IF(Z20="Europe","Europe","Other") -> Other
A21: =VLOOKUP(Q21,regions_fabio!$A$2:$C$192,3,0) -> ARM | B21: =IFERROR(VLOOKUP(A21,polities_whep!$A$1:$G$199,2,0),"") -> Armenia | C21: 1 | D21: 1 | E21: ARM | F21: =VLOOKUP(D21,FAO_areas!$A$2:$C$246,3,0) -> Armenia | G21: FALSE | H21: Armenia | I21: Armenia | J21: Armenia | K21: 1 | L21: Armenia | M21: 51 | N21: 51 | O21: 11 | P21: TRUE | Q21: 1 | S21: Former USSR | T21: 1 | U21: Armenia | V21: Central Asia and Russian Federation | W21: South and Central Asia | X21: CAS & Russia | Y21: Western Asia | Z21: Asia | AA21: Europe and Central Asia | AB21: Central and Western Asia | AC21: Western Asia | AD21: Emerging | AE21: Annex_II | AF21: FSU | AG21: FSU | AH21: no_mech | AI21: =IF(Z21="Europe","Europe","Other") -> Other
A22: RASI | B22: =IFERROR(VLOOKUP(A22,polities_whep!$A$1:$G$199,2,0),"") -> Asia Other | C22: 18 | D22: 18 | E22: BTN | F22: =VLOOKUP(D22,FAO_areas!$A$2:$C$246,3,0) -> Bhutan | G22: FALSE | H22: Bhutan | I22: Bhutan | K22: 18 | L22: Bhutan | M22: 64 | N22: 64 | O22: 13 | P22: FALSE | Q22: 999 | S22: South Asia | T22: 1 | U22: Bhutan | V22: Southern Asia | W22: South and Central Asia | X22: Southern Asia | Y22: Southern Asia | Z22: Asia | AA22: Asia and the Pacific | AB22: Southern Asia | AC22: Southern Asia | AD22: Emerging | AE22: Annex_II | AF22: Southern Asia | AG22: SE-Asia | AH22: no_mech | AI22: =IF(Z22="Europe","Europe","Other") -> Other
A23: RASI | B23: =IFERROR(VLOOKUP(A23,polities_whep!$A$1:$G$199,2,0),"") -> Asia Other | C23: 24 | D23: 24 | E23: IOT | F23: =VLOOKUP(D23,FAO_areas!$A$2:$C$246,3,0) -> #N/A | G23: FALSE | H23: British Indian Ocean Territory | K23: 999 | L23: Global average | M23: 86 | N23: 86 | O23: 13 | P23: FALSE | Q23: 999 | S23: South Asia | T23: 1 | U23: British Indian Ocean Territory | V23: Southern Asia | W23: South and Central Asia | X23: Southern Asia | Y23: Sub-Saharan Africa | Z23: Asia | AA23: Asia and the Pacific | AB23: Southern Asia | AC23: Southern Asia | AD23: Emerging | AE23: Annex_II | AF23: Southern Asia | AG23: SE-Asia | AH23: no_mech | AI23: =IF(Z23="Europe","Europe","Other") -> Other
A24: RASI | B24: =IFERROR(VLOOKUP(A24,polities_whep!$A$1:$G$199,2,0),"") -> Asia Other | C24: 161 | D24: 164 | E24: PCI | F24: =VLOOKUP(D24,FAO_areas!$A$2:$C$246,3,0) -> #N/A | G24: FALSE | H24: Pacific Islands Trust Territory | K24: 999 | L24: Global average | M24: NA | N24: 582 | O24: 15 | P24: FALSE | Q24: 999 | S24: South East Asia | T24: 1 | U24: Pacific Islands Trust Territory | V24: Southeastern Asia | W24: South and Central Asia | X24: S&E Asia | Y24: Australia and New Zealand | Z24: Asia | AA24: Asia and the Pacific | AB24: South-Eastern Asia and the Pacific | AC24: Pacific Islands | AD24: Emerging | AE24: Annex_II | AF24: Pacific | AG24: AUS | AH24: mech | AI24: =IF(Z24="Europe","Europe","Other") -> Other
A25: RASI | B25: Asia Other
A26: =VLOOKUP(Q26,regions_fabio!$A$2:$C$192,3,0) -> AUS | B26: =IFERROR(VLOOKUP(A26,polities_whep!$A$1:$G$199,2,0),"") -> Australia | C26: 10 | D26: 10 | E26: AUS | F26: =VLOOKUP(D26,FAO_areas!$A$2:$C$246,3,0) -> Australia | G26: FALSE | H26: Australia | I26: Australia | J26: Australia | K26: 10 | L26: Australia | M26: 36 | N26: 36 | O26: 16 | P26: TRUE | Q26: 10 | S26: Oceania | T26: 1 | U26: Australia | V26: Australia and Oceania | W26: North America and Oceania | X26: Oceania | Y26: Australia and New Zealand | Z26: Oceania | AA26: Asia and the Pacific | AB26: South-Eastern Asia and the Pacific | AC26: Pacific Islands | AD26: Advanced | AE26: Annex_I | AF26: Pacific | AG26: AUS | AH26: mech | AI26: =IF(Z26="Europe","Europe","Other") -> Other
A27: =VLOOKUP(Q27,regions_fabio!$A$2:$C$192,3,0) -> AUT | B27: =IFERROR(VLOOKUP(A27,polities_whep!$A$1:$G$199,2,0),"") -> Austria | C27: 11 | D27: 11 | E27: AUT | F27: =VLOOKUP(D27,FAO_areas!$A$2:$C$246,3,0) -> Austria | G27: TRUE | H27: Austria | I27: Austria | J27: Austria | K27: 11 | L27: Austria | M27: 40 | N27: 40 | O27: 9 | P27: TRUE | Q27: 11 | S27: OECD Europe | T27: 1 | U27: Austria | V27: Western Europe | W27: West Europe | X27: Europe | Y27: Western Europe | Z27: Europe | AA27: Europe and Central Asia | AB27: Northern, Southern and Western Europe | AC27: Western Europe | AD27: Advanced | AE27: Annex_I | AF27: Western Europe | AG27: Europe | AH27: mech | AI27: =IF(Z27="Europe","Europe","Other") -> Europe
A28: =VLOOKUP(Q28,regions_fabio!$A$2:$C$192,3,0) -> AZE | B28: =IFERROR(VLOOKUP(A28,polities_whep!$A$1:$G$199,2,0),"") -> Azerbaijan | C28: 52 | D28: 52 | E28: AZE | F28: =VLOOKUP(D28,FAO_areas!$A$2:$C$246,3,0) -> Azerbaijan | G28: FALSE | H28: Azerbaijan | I28: Azerbaijan | J28: Azerbaijan | K28: 52 | L28: Azerbaijan | M28: 31 | N28: 31 | O28: 11 | P28: TRUE | Q28: 52 | S28: Former USSR | T28: 1 | U28: Azerbaijan | V28: Central Asia and Russian Federation | W28: South and Central Asia | X28: CAS & Russia | Y28: Western Asia | Z28: Asia | AA28: Europe and Central Asia | AB28: Central and Western Asia | AC28: Western Asia | AD28: Emerging | AE28: Annex_II | AF28: FSU | AG28: FSU | AH28: no_mech | AI28: =IF(Z28="Europe","Europe","Other") -> Other
A29: =VLOOKUP(Q29,regions_fabio!$A$2:$C$192,3,0) -> BHS | B29: =IFERROR(VLOOKUP(A29,polities_whep!$A$1:$G$199,2,0),"") -> Bahamas | C29: 12 | D29: 12 | E29: BHS | F29: =VLOOKUP(D29,FAO_areas!$A$2:$C$246,3,0) -> Bahamas | G29: FALSE | H29: Bahamas | I29: Bahamas, The | K29: 12 | L29: Bahamas | M29: 44 | N29: 44 | O29: 3 | P29: TRUE | Q29: 12 | S29: Central America | T29: 1 | U29: Bahamas | V29: Latin America and the Caribbean | W29: Latin America and Caribbean | X29: LACA | Y29: Latin America and the Caribbean | Z29: Americas | AA29: Americas | AB29: Latin America and the Caribbean | AC29: Caribbean | AD29: Emerging | AE29: Annex_II | AF29: Caribbean & Centra Am. | AG29: LACA | AH29: no_mech | AI29: =IF(Z29="Europe","Europe","Other") -> Other
A30: =VLOOKUP(Q30,regions_fabio!$A$2:$C$192,3,0) -> BHR | B30: =IFERROR(VLOOKUP(A30,polities_whep!$A$1:$G$199,2,0),"") -> Bahrain | C30: 13 | D30: 13 | E30: BHR | F30: =VLOOKUP(D30,FAO_areas!$A$2:$C$246,3,0) -> Bahrain | G30: FALSE | H30: Bahrain | I30: Bahrain | J30: Bahrain | K30: 13 | L30: Bahrain | M30: 48 | N30: 48 | O30: 12 | P30: TRUE | Q30: 13 | S30: Middle East | T30: 1 | U30: Bahrain | V30: Northern Africa and Western Asia | W30: North Africa and West Asia | X30: MENA | Y30: Western Asia | Z30: Asia | AA30: Arab States | AB30: Arab States | AC30: Arab States | AD30: Emerging | AE30: Annex_II | AF30: Western Asia | AG30: MENA | AH30: no_mech | AI30: =IF(Z30="Europe","Europe","Other") -> Other
A31: =VLOOKUP(Q31,regions_fabio!$A$2:$C$192,3,0) -> BGD | B31: =IFERROR(VLOOKUP(A31,polities_whep!$A$1:$G$199,2,0),"") -> Bangladesh | C31: 16 | D31: 16 | E31: BGD | F31: =VLOOKUP(D31,FAO_areas!$A$2:$C$246,3,0) -> Bangladesh | G31: FALSE | H31: Bangladesh | I31: Bangladesh | J31: Bangladesh | K31: 16 | L31: Bangladesh | M31: 50 | N31: 50 | O31: 13 | P31: TRUE | Q31: 16 | S31: South Asia | T31: 1 | U31: Bangladesh | V31: Southern Asia | W31: South and Central Asia | X31: Southern Asia | Y31: Southern Asia | Z31: Asia | AA31: Asia and the Pacific | AB31: Southern Asia | AC31: Southern Asia | AD31: Emerging | AE31: Annex_II | AF31: Southern Asia | AG31: SE-Asia | AH31: no_mech | AI31: =IF(Z31="Europe","Europe","Other") -> Other
A32: =VLOOKUP(Q32,regions_fabio!$A$2:$C$192,3,0) -> BRB | B32: =IFERROR(VLOOKUP(A32,polities_whep!$A$1:$G$199,2,0),"") -> Barbados | C32: 14 | D32: 14 | E32: BRB | F32: =VLOOKUP(D32,FAO_areas!$A$2:$C$246,3,0) -> Barbados | G32: FALSE | H32: Barbados | I32: Barbados | K32: 14 | L32: Barbados | M32: 52 | N32: 52 | O32: 3 | P32: TRUE | Q32: 14 | S32: Central America | T32: 1 | U32: Barbados | V32: Latin America and the Caribbean | W32: Latin America and Caribbean | X32: LACA | Y32: Latin America and the Caribbean | Z32: Americas | AA32: Americas | AB32: Latin America and the Caribbean | AC32: Caribbean | AD32: Emerging | AE32: Annex_II | AF32: Caribbean & Centra Am. | AG32: LACA | AH32: no_mech | AI32: =IF(Z32="Europe","Europe","Other") -> Other
A33: =VLOOKUP(Q33,regions_fabio!$A$2:$C$192,3,0) -> BLR | B33: =IFERROR(VLOOKUP(A33,polities_whep!$A$1:$G$199,2,0),"") -> Belarus | C33: 57 | D33: 57 | E33: BLR | F33: =VLOOKUP(D33,FAO_areas!$A$2:$C$246,3,0) -> Belarus | G33: FALSE | H33: Belarus | I33: Belarus | J33: Belarus | K33: 57 | L33: Belarus | M33: 112 | N33: 112 | O33: 11 | P33: TRUE | Q33: 57 | S33: Former USSR | T33: 1 | U33: Belarus | V33: Central Asia and Russian Federation | W33: South and Central Asia | X33: CAS & Russia | Y33: Eastern Europe | Z33: Europe | AA33: Europe and Central Asia | AB33: Eastern Europe | AC33: Eastern Europe | AD33: Emerging | AE33: Annex_I | AF33: FSU | AG33: FSU | AH33: mech | AI33: =IF(Z33="Europe","Europe","Other") -> Europe
